Workbook

Sheet 2026 Miami
A1: 2024 Kepners | J1: Round | K1: 1 | L1: 2 | M1: 3 | N1: 4 | O1: 5 | P1: 6 | Q1: 7 | R1: 8 | S1: 9 | T1: 10 | U1: 11 | V1: 12 | W1: 13 | X1: 14 | Y1: 15 | Z1: 16
A2: Download List from: https://www.4for4.com/adp?paging=0 | B2: Research Action Items | H2: First Pick | I2: 3 | J2: Targets | K2: =COUNTIF($D$7:$D$301, K1) -> 3 | L2: =COUNTIF($D$7:$D$301, L1) -> 19 | M2: =COUNTIF($D$7:$D$301, M1) -> 5 | N2: =COUNTIF($D$7:$D$301, N1) -> 19 | O2: =COUNTIF($D$7:$D$301, O1) -> 5 | P2: =COUNTIF($D$7:$D$301, P1) -> 17 | Q2: =COUNTIF($D$7:$D$301, Q1) -> 8 | R2: =COUNTIF($D$7:$D$301, R1) -> 0 | ... Z2: =COUNTIF($D$7:$D$301, Z1) -> 0
B3: 1. Finalize Keeper Dat | H3: Second Pick | I3: =24-I2+1 -> 22 | J3: Cum Targets | K3: =K2 -> 3 | L3: =K3+L2 -> 22 | M3: =L3+M2 -> 27 | N3: =M3+N2 -> 46 | O3: =N3+O2 -> 51 | P3: =O3+P2 -> 68 | Q3: =P3+Q2 -> 76 | R3: =Q3+R2 -> 76 | S3: =R3+S2 -> 97 | ... Z3: =Y3+Z2 -> 106
B4: 2. Populate Target Rounds | J4: My Pick | K4: =I2 -> 3 | L4: =I3 -> 22 | M4: =L4+5 -> 27 | N4: =M4+19 -> 46 | O4: =N4+5 -> 51 | P4: =O4+19 -> 70 | Q4: =P4+5 -> 75 | R4: =Q4+19 -> 94 | S4: =R4+5 -> 99 | T4: =S4+19 -> 118 | U4: =T4+5 -> 123 | V4: =U4+19 -> 142 | W4: =V4+5 -> 147 | X4: =W4+19 -> 166 | Y4: =X4+5 -> 171 | Z4: =Y4+19 -> 190
J5: Enough Targets? | K5: =K3-K4 -> 0 | L5: =L3-L4 -> 0 | M5: =M3-M4 -> 0 | N5: =N3-N4 -> 0 | O5: =O3-O4 -> 0 | P5: =P3-P4 -> -2 | Q5: =Q3-Q4 -> 1 | R5: =R3-R4 -> -18 | ... Z5: =Z3-Z4 -> -84
A6: My Team | B6: Average Round | C6: Available? | D6: Target Round | E6: Draft Prep Mock | F6: Like | G6: Player | H6: Team | I6: Position | J6: Tier | K6: Sean Pos Rank | L6: Yahoo Avg Rnd | M6: Y! | N6: Avg Dif | O6: Underdog | P6: Underdog Diff | Q6: CBS | R6: ESPN | S6: FFPC | T6: BB10s | U6: NFL | V6: AVG RK | W6: Avg Rd | X6: My Diff | Y6: Diff from Old Rank | Z6: Notes
B7: =IFERROR(INT(AVERAGE(Q7:U7)/12)+1, INT(AVERAGE(M7)/12)+1) -> 1 | C7: No | D7: 1 | F7: =VLOOKUP(G7, SeanRanks!$A$2:$E$302, 4, FALSE) -> 0 | G7: Christian McCaffrey | H7: =VLOOKUP($G7, 'ADP Data'!$C$4:$Q$300, 2, FALSE) -> SF | I7: =VLOOKUP(G7, 'ADP Data'!$C$4:$R$498, 12, FALSE) -> 7 | J7: =VLOOKUP($G7, SeanRanks!$A$2:$H$303, 5, FALSE) -> 0 | K7: =VLOOKUP($G7, SeanRanks!$A$2:$H$303, 6, FALSE) -> RB1 - 1 - Elite floor/ceiling | L7: =IFERROR(INT(M7/8)+1, 16) -> 2 | M7: =VLOOKUP($G7, 'ADP Data'!$C$4:$Q$300, 9, FALSE) -> 10 | N7: =M7-V7 -> 2 | O7: =VLOOKUP($G7, 'ADP Data'!$C$4:$Q$300, 3, FALSE) -> 8 | P7: =M7-O7 -> 2 | Q7: =VLOOKUP($G7, 'ADP Data'!$C$4:$Q$300, 4, FALSE) -> 7 | R7: =VLOOKUP($G7, 'ADP Data'!$C$4:$Q$300, 5, FALSE) -> 7 | S7: =VLOOKUP($G7, 'ADP Data'!$C$4:$Q$300, 6, FALSE) -> 8 | T7: =VLOOKUP($G7, 'ADP Data'!$C$4:$Q$300, 7, FALSE) -> 7 | U7: =VLOOKUP($G7, 'ADP Data'!$C$4:$Q$300, 8, FALSE) -> 11 | V7: =INT(AVERAGE(M7, O7,Q7:U7)) -> 8 | W7: =IFERROR(INT(V7/8)+1, 16) -> 2 | X7: =D7-W7 -> -1 | Y7: =VLOOKUP($G7, SeanRanks!$A$2:$K$303, 10, FALSE)-V7 -> 1 | Z7: =IF(VLOOKUP($G7, SeanRanks!$A$2:$H$303, 7, FALSE)=0, "", VLOOKUP($G7, SeanRanks!$A$2:$H$303, 7, FALSE)) -> 4
A8: Yes | B8: =IFERROR(INT(AVERAGE(Q8:U8)/12)+1, INT(AVERAGE(M8)/12)+1) -> 3 | C8: No | D8: 1 | F8: =VLOOKUP(G8, SeanRanks!$A$2:$E$302, 4, FALSE) -> 0 | G8: Tyreek Hill | H8: =VLOOKUP($G8, 'ADP Data'!$C$4:$Q$300, 2, FALSE) -> MIA | I8: =VLOOKUP(G8, 'ADP Data'!$C$4:$R$498, 12, FALSE) -> 33 | J8: =VLOOKUP($G8, SeanRanks!$A$2:$H$303, 5, FALSE) -> Yes | K8: =IF(VLOOKUP($G8, SeanRanks!$A$2:$H$303, 6, FALSE)=0, "", VLOOKUP($G8, SeanRanks!$A$2:$H$303, 6, FALSE)) -> WR2 - 1 - WR1 upside | L8: =IFERROR(INT(M8/8)+1, 16) -> 4 | M8: =VLOOKUP($G8, 'ADP Data'!$C$4:$Q$300, 9, FALSE) -> 27 | N8: =M8-V8 -> -7 | O8: =VLOOKUP($G8, 'ADP Data'!$C$4:$Q$300, 3, FALSE) -> 39 | P8: =M8-O8 -> -12 | Q8: =VLOOKUP($G8, 'ADP Data'!$C$4:$Q$300, 4, FALSE) -> 31 | R8: =VLOOKUP($G8, 'ADP Data'!$C$4:$Q$300, 5, FALSE) -> 36 | S8: =VLOOKUP($G8, 'ADP Data'!$C$4:$Q$300, 6, FALSE) -> 36 | T8: =VLOOKUP($G8, 'ADP Data'!$C$4:$Q$300, 7, FALSE) -> 33 | U8: =VLOOKUP($G8, 'ADP Data'!$C$4:$Q$300, 8, FALSE) -> 36 | V8: =INT(AVERAGE(M8, O8,Q8:U8)) -> 34 | W8: =IFERROR(INT(V8/8)+1, 16) -> 5 | X8: =D8-W8 -> -4 | Y8: =VLOOKUP($G8, SeanRanks!$A$2:$K$303, 10, FALSE)-V8 -> 8 | Z8: =IF(VLOOKUP($G8, SeanRanks!$A$2:$H$303, 7, FALSE)=0, "", VLOOKUP($G8, SeanRanks!$A$2:$H$303, 7, FALSE)) -> 16
B9: =IFERROR(INT(AVERAGE(Q9:U9)/12)+1, INT(AVERAGE(M9)/12)+1) -> 1 | C9: No | D9: 1 | E9: X | F9: =VLOOKUP(G9, SeanRanks!$A$2:$E$302, 4, FALSE) -> 0 | G9: CeeDee Lamb | H9: =VLOOKUP($G9, 'ADP Data'!$C$4:$Q$300, 2, FALSE) -> DAL | I9: =VLOOKUP(G9, 'ADP Data'!$C$4:$R$498, 12, FALSE) -> 3 | J9: =VLOOKUP($G9, SeanRanks!$A$2:$H$303, 5, FALSE) -> 0 | K9: =IF(VLOOKUP($G9, SeanRanks!$A$2:$H$303, 6, FALSE)=0, "", VLOOKUP($G9, SeanRanks!$A$2:$H$303, 6, FALSE)) -> WR1 - 1 - Elite | L9: =IFERROR(INT(M9/8)+1, 16) -> 1 | M9: =VLOOKUP($G9, 'ADP Data'!$C$4:$Q$300, 9, FALSE) -> 6 | N9: =M9-V9 -> 2 | O9: =VLOOKUP($G9, 'ADP Data'!$C$4:$Q$300, 3, FALSE) -> 5 | P9: =M9-O9 -> 1 | Q9: =VLOOKUP($G9, 'ADP Data'!$C$4:$Q$300, 4, FALSE) -> 6 | R9: =VLOOKUP($G9, 'ADP Data'!$C$4:$Q$300, 5, FALSE) -> 5 | S9: =VLOOKUP($G9, 'ADP Data'!$C$4:$Q$300, 6, FALSE) -> 4 | T9: =VLOOKUP($G9, 'ADP Data'!$C$4:$Q$300, 7, FALSE) -> 4 | U9: =VLOOKUP($G9, 'ADP Data'!$C$4:$Q$300, 8, FALSE) -> 3 | V9: =INT(AVERAGE(M9, O9,Q9:U9)) -> 4 | W9: =IFERROR(INT(V9/8)+1, 16) -> 1 | X9: =D9-W9 -> 0 | Y9: =VLOOKUP($G9, SeanRanks!$A$2:$K$303, 10, FALSE)-V9 -> 1 | Z9: =IF(VLOOKUP($G9, SeanRanks!$A$2:$H$303, 7, FALSE)=0, "", VLOOKUP($G9, SeanRanks!$A$2:$H$303, 7, FALSE)) -> 3
B10: =IFERROR(INT(AVERAGE(Q10:U10)/12)+1, INT(AVERAGE(M10)/12)+1) -> 4 | C10: No | D10: 2 | F10: =VLOOKUP(G10, SeanRanks!$A$2:$E$302, 4, FALSE) -> 0 | G10: Breece Hall | H10: =VLOOKUP($G10, 'ADP Data'!$C$4:$Q$300, 2, FALSE) -> NYJ | I10: =VLOOKUP(G10, 'ADP Data'!$C$4:$R$498, 12, FALSE) -> 47 | J10: =VLOOKUP($G10, SeanRanks!$A$2:$H$303, 5, FALSE) -> 0 | K10: =IF(VLOOKUP($G10, SeanRanks!$A$2:$H$303, 6, FALSE)=0, "", VLOOKUP($G10, SeanRanks!$A$2:$H$303, 6, FALSE)) -> RB2 - 1 - Clear path to spikes | L10: =IFERROR(INT(M10/8)+1, 16) -> 5 | M10: =VLOOKUP($G10, 'ADP Data'!$C$4:$Q$300, 9, FALSE) -> 32 | N10: =M10-V10 -> -7 | O10: =VLOOKUP($G10, 'ADP Data'!$C$4:$Q$300, 3, FALSE) -> 41 | P10: =M10-O10 -> -9 | Q10: =VLOOKUP($G10, 'ADP Data'!$C$4:$Q$300, 4, FALSE) -> 51 | R10: =VLOOKUP($G10, 'ADP Data'!$C$4:$Q$300, 5, FALSE) -> 41 | S10: =VLOOKUP($G10, 'ADP Data'!$C$4:$Q$300, 6, FALSE) -> 42 | T10: =VLOOKUP($G10, 'ADP Data'!$C$4:$Q$300, 7, FALSE) -> 39 | U10: =VLOOKUP($G10, 'ADP Data'!$C$4:$Q$300, 8, FALSE) -> 31 | V10: =INT(AVERAGE(M10, O10,Q10:U10)) -> 39 | W10: =IFERROR(INT(V10/8)+1, 16) -> 5 | X10: =D10-W10 -> -3 | Y10: =VLOOKUP($G10, SeanRanks!$A$2:$K$303, 10, FALSE)-V10 -> 11 | Z10: =IF(VLOOKUP($G10, SeanRanks!$A$2:$H$303, 7, FALSE)=0, "", VLOOKUP($G10, SeanRanks!$A$2:$H$303, 7, FALSE)) -> 16
B11: =IFERROR(INT(AVERAGE(Q11:U11)/12)+1, INT(AVERAGE(M11)/12)+1) -> 1 | C11: No | D11: 2 | F11: =VLOOKUP(G11, SeanRanks!$A$2:$E$302, 4, FALSE) -> 0 | G11: Bijan Robinson | H11: =VLOOKUP($G11, 'ADP Data'!$C$4:$Q$300, 2, FALSE) -> ATL | I11: =VLOOKUP(G11, 'ADP Data'!$C$4:$R$498, 12, FALSE) -> 2 | J11: =VLOOKUP($G11, SeanRanks!$A$2:$H$303, 5, FALSE) -> 0 | K11: =IF(VLOOKUP($G11, SeanRanks!$A$2:$H$303, 6, FALSE)=0, "", VLOOKUP($G11, SeanRanks!$A$2:$H$303, 6, FALSE)) -> RB1 - 1 - Elite floor/ceiling | L11: =IFERROR(INT(M11/8)+1, 16) -> 1 | M11: =VLOOKUP($G11, 'ADP Data'!$C$4:$Q$300, 9, FALSE) -> 3 | N11: =M11-V11 -> 1 | O11: =VLOOKUP($G11, 'ADP Data'!$C$4:$Q$300, 3, FALSE) -> 2 | P11: =M11-O11 -> 1 | Q11: =VLOOKUP($G11, 'ADP Data'!$C$4:$Q$300, 4, FALSE) -> 2 | R11: =VLOOKUP($G11, 'ADP Data'!$C$4:$Q$300, 5, FALSE) -> 2 | S11: =VLOOKUP($G11, 'ADP Data'!$C$4:$Q$300, 6, FALSE) -> 2 | T11: =VLOOKUP($G11, 'ADP Data'!$C$4:$Q$300, 7, FALSE) -> 2 | U11: =VLOOKUP($G11, 'ADP Data'!$C$4:$Q$300, 8, FALSE) -> 2 | V11: =INT(AVERAGE(M11, O11,Q11:U11)) -> 2 | W11: =IFERROR(INT(V11/8)+1, 16) -> 1 | X11: =D11-W11 -> 1 | Y11: =VLOOKUP($G11, SeanRanks!$A$2:$K$303, 10, FALSE)-V11 -> 0 | Z11: =IF(VLOOKUP($G11, SeanRanks!$A$2:$H$303, 7, FALSE)=0, "", VLOOKUP($G11, SeanRanks!$A$2:$H$303, 7, FALSE)) -> 1
B12: =IFERROR(INT(AVERAGE(Q12:U12)/12)+1, INT(AVERAGE(M12)/12)+1) -> 1 | C12: No | D12: 2 | F12: =VLOOKUP(G12, SeanRanks!$A$2:$E$302, 4, FALSE) -> 0 | G12: Ja'Marr Chase | H12: =VLOOKUP($G12, 'ADP Data'!$C$4:$Q$300, 2, FALSE) -> CIN | I12: =VLOOKUP(G12, 'ADP Data'!$C$4:$R$498, 12, FALSE) -> 1 | J12: =VLOOKUP($G12, SeanRanks!$A$2:$H$303, 5, FALSE) -> 0 | K12: =IF(VLOOKUP($G12, SeanRanks!$A$2:$H$303, 6, FALSE)=0, "", VLOOKUP($G12, SeanRanks!$A$2:$H$303, 6, FALSE)) -> WR1 - 1 - Elite | L12: =IFERROR(INT(M12/8)+1, 16) -> 1 | M12: =VLOOKUP($G12, 'ADP Data'!$C$4:$Q$300, 9, FALSE) -> 1 | N12: =M12-V12 -> 0 | O12: =VLOOKUP($G12, 'ADP Data'!$C$4:$Q$300, 3, FALSE) -> 1 | P12: =M12-O12 -> 0 | Q12: =VLOOKUP($G12, 'ADP Data'!$C$4:$Q$300, 4, FALSE) -> 1 | R12: =VLOOKUP($G12, 'ADP Data'!$C$4:$Q$300, 5, FALSE) -> 1 | S12: =VLOOKUP($G12, 'ADP Data'!$C$4:$Q$300, 6, FALSE) -> 1 | T12: =VLOOKUP($G12, 'ADP Data'!$C$4:$Q$300, 7, FALSE) -> 1 | U12: =VLOOKUP($G12, 'ADP Data'!$C$4:$Q$300, 8, FALSE) -> 1 | V12: =INT(AVERAGE(M12, O12,Q12:U12)) -> 1 | W12: =IFERROR(INT(V12/8)+1, 16) -> 1 | X12: =D12-W12 -> 1 | Y12: =VLOOKUP($G12, SeanRanks!$A$2:$K$303, 10, FALSE)-V12 -> 0 | Z12: =IF(VLOOKUP($G12, SeanRanks!$A$2:$H$303, 7, FALSE)=0, "", VLOOKUP($G12, SeanRanks!$A$2:$H$303, 7, FALSE)) -> 1
B13: =IFERROR(INT(AVERAGE(Q13:U13)/12)+1, INT(AVERAGE(M13)/12)+1) -> 2 | C13: No | F13: =VLOOKUP(G13, SeanRanks!$A$2:$E$302, 4, FALSE) -> 0 | G13: A.J. Brown | H13: =VLOOKUP($G13, 'ADP Data'!$C$4:$Q$300, 2, FALSE) -> PHI | I13: =VLOOKUP(G13, 'ADP Data'!$C$4:$R$498, 12, FALSE) -> 17 | J13: =VLOOKUP($G13, SeanRanks!$A$2:$H$303, 5, FALSE) -> 0 | K13: =IF(VLOOKUP($G13, SeanRanks!$A$2:$H$303, 6, FALSE)=0, "", VLOOKUP($G13, SeanRanks!$A$2:$H$303, 6, FALSE)) -> WR1 - 3 - Inconsistent | L13: =IFERROR(INT(M13/8)+1, 16) -> 3 | M13: =VLOOKUP($G13, 'ADP Data'!$C$4:$Q$300, 9, FALSE) -> 18 | N13: =M13-V13 -> -2 | O13: =VLOOKUP($G13, 'ADP Data'!$C$4:$Q$300, 3, FALSE) -> 27 | P13: =M13-O13 -> -9 | Q13: =VLOOKUP($G13, 'ADP Data'!$C$4:$Q$300, 4, FALSE) -> 18 | R13: =VLOOKUP($G13, 'ADP Data'!$C$4:$Q$300, 5, FALSE) -> 22 | S13: =VLOOKUP($G13, 'ADP Data'!$C$4:$Q$300, 6, FALSE) -> 23 | T13: =VLOOKUP($G13, 'ADP Data'!$C$4:$Q$300, 7, FALSE) -> 21 | U13: =VLOOKUP($G13, 'ADP Data'!$C$4:$Q$300, 8, FALSE) -> 15 | V13: =INT(AVERAGE(M13, O13,Q13:U13)) -> 20 | W13: =IFERROR(INT(V13/8)+1, 16) -> 3 | X13: =D13-W13 -> -3 | Y13: =VLOOKUP($G13, SeanRanks!$A$2:$K$303, 10, FALSE)-V13 -> -2 | Z13: =IF(VLOOKUP($G13, SeanRanks!$A$2:$H$303, 7, FALSE)=0, "", VLOOKUP($G13, SeanRanks!$A$2:$H$303, 7, FALSE)) -> 11
B14: =IFERROR(INT(AVERAGE(Q14:U14)/12)+1, INT(AVERAGE(M14)/12)+1) -> 1 | C14: No | F14: =VLOOKUP(G14, SeanRanks!$A$2:$E$302, 4, FALSE) -> 0 | G14: Justin Jefferson | H14: =VLOOKUP($G14, 'ADP Data'!$C$4:$Q$300, 2, FALSE) -> MIN | I14: =VLOOKUP(G14, 'ADP Data'!$C$4:$R$498, 12, FALSE) -> 5 | J14: =VLOOKUP($G14, SeanRanks!$A$2:$H$303, 5, FALSE) -> 0 | K14: =IF(VLOOKUP($G14, SeanRanks!$A$2:$H$303, 6, FALSE)=0, "", VLOOKUP($G14, SeanRanks!$A$2:$H$303, 6, FALSE)) -> WR1 - 1 - Elite | L14: =IFERROR(INT(M14/8)+1, 16) -> 1 | M14: =VLOOKUP($G14, 'ADP Data'!$C$4:$Q$300, 9, FALSE) -> 5 | N14: =M14-V14 -> 0 | O14: =VLOOKUP($G14, 'ADP Data'!$C$4:$Q$300, 3, FALSE) -> 6 | P14: =M14-O14 -> -1 | Q14: =VLOOKUP($G14, 'ADP Data'!$C$4:$Q$300, 4, FALSE) -> 4 | R14: =VLOOKUP($G14, 'ADP Data'!$C$4:$Q$300, 5, FALSE) -> 3 | S14: =VLOOKUP($G14, 'ADP Data'!$C$4:$Q$300, 6, FALSE) -> 6 | T14: =VLOOKUP($G14, 'ADP Data'!$C$4:$Q$300, 7, FALSE) -> 6 | U14: =VLOOKUP($G14, 'ADP Data'!$C$4:$Q$300, 8, FALSE) -> 5 | V14: =INT(AVERAGE(M14, O14,Q14:U14)) -> 5 | W14: =IFERROR(INT(V14/8)+1, 16) -> 1 | X14: =D14-W14 -> -1 | Y14: =VLOOKUP($G14, SeanRanks!$A$2:$K$303, 10, FALSE)-V14 -> 1 | Z14: =IF(VLOOKUP($G14, SeanRanks!$A$2:$H$303, 7, FALSE)=0, "", VLOOKUP($G14, SeanRanks!$A$2:$H$303, 7, FALSE)) -> 2
B15: =IFERROR(INT(AVERAGE(Q15:U15)/12)+1, INT(AVERAGE(M15)/12)+1) -> 1 | C15: No | D15: 2 | F15: =VLOOKUP(G15, SeanRanks!$A$2:$E$302, 4, FALSE) -> 0 | G15: Amon-Ra St. Brown | H15: =VLOOKUP($G15, 'ADP Data'!$C$4:$Q$300, 2, FALSE) -> DET | I15: =VLOOKUP(G15, 'ADP Data'!$C$4:$R$498, 12, FALSE) -> 9 | J15: =VLOOKUP($G15, SeanRanks!$A$2:$H$303, 5, FALSE) -> 0 | K15: =IF(VLOOKUP($G15, SeanRanks!$A$2:$H$303, 6, FALSE)=0, "", VLOOKUP($G15, SeanRanks!$A$2:$H$303, 6, FALSE)) -> WR1 - 2 - High Floor | L15: =IFERROR(INT(M15/8)+1, 16) -> 2 | M15: =VLOOKUP($G15, 'ADP Data'!$C$4:$Q$300, 9, FALSE) -> 8 | N15: =M15-V15 -> -1 | O15: =VLOOKUP($G15, 'ADP Data'!$C$4:$Q$300, 3, FALSE) -> 12 | P15: =M15-O15 -> -4 | Q15: =VLOOKUP($G15, 'ADP Data'!$C$4:$Q$300, 4, FALSE) -> 8 | R15: =VLOOKUP($G15, 'ADP Data'!$C$4:$Q$300, 5, FALSE) -> 11 | S15: =VLOOKUP($G15, 'ADP Data'!$C$4:$Q$300, 6, FALSE) -> 11 | T15: =VLOOKUP($G15, 'ADP Data'!$C$4:$Q$300, 7, FALSE) -> 9 | U15: =VLOOKUP($G15, 'ADP Data'!$C$4:$Q$300, 8, FALSE) -> 8 | V15: =INT(AVERAGE(M15, O15,Q15:U15)) -> 9 | W15: =IFERROR(INT(V15/8)+1, 16) -> 2 | X15: =D15-W15 -> 0 | Y15: =VLOOKUP($G15, SeanRanks!$A$2:$K$303, 10, FALSE)-V15 -> -1 | Z15: =IF(VLOOKUP($G15, SeanRanks!$A$2:$H$303, 7, FALSE)=0, "", VLOOKUP($G15, SeanRanks!$A$2:$H$303, 7, FALSE)) -> 6
B16: =IFERROR(INT(AVERAGE(Q16:U16)/12)+1, INT(AVERAGE(M16)/12)+1) -> 2 | C16: No | F16: =VLOOKUP(G16, SeanRanks!$A$2:$E$302, 4, FALSE) -> 0 | G16: Jonathan Taylor | H16: =VLOOKUP($G16, 'ADP Data'!$C$4:$Q$300, 2, FALSE) -> IND | I16: =VLOOKUP(G16, 'ADP Data'!$C$4:$R$498, 12, FALSE) -> 20 | J16: =VLOOKUP($G16, SeanRanks!$A$2:$H$303, 5, FALSE) -> No | K16: =IF(VLOOKUP($G16, SeanRanks!$A$2:$H$303, 6, FALSE)=0, "", VLOOKUP($G16, SeanRanks!$A$2:$H$303, 6, FALSE)) -> RB1 - 2 - Elite ceiling/questions | L16: =IFERROR(INT(M16/8)+1, 16) -> 3 | M16: =VLOOKUP($G16, 'ADP Data'!$C$4:$Q$300, 9, FALSE) -> 20 | N16: =M16-V16 -> 1 | O16: =VLOOKUP($G16, 'ADP Data'!$C$4:$Q$300, 3, FALSE) -> 21 | P16: =M16-O16 -> -1 | Q16: =VLOOKUP($G16, 'ADP Data'!$C$4:$Q$300, 4, FALSE) -> 15 | R16: =VLOOKUP($G16, 'ADP Data'!$C$4:$Q$300, 5, FALSE) -> 20 | S16: =VLOOKUP($G16, 'ADP Data'!$C$4:$Q$300, 6, FALSE) -> 21 | T16: =VLOOKUP($G16, 'ADP Data'!$C$4:$Q$300, 7, FALSE) -> 20 | U16: =VLOOKUP($G16, 'ADP Data'!$C$4:$Q$300, 8, FALSE) -> 22 | V16: =INT(AVERAGE(M16, O16,Q16:U16)) -> 19 | W16: =IFERROR(INT(V16/8)+1, 16) -> 3 | X16: =D16-W16 -> -3 | Y16: =VLOOKUP($G16, SeanRanks!$A$2:$K$303, 10, FALSE)-V16 -> 0 | Z16: =IF(VLOOKUP($G16, SeanRanks!$A$2:$H$303, 7, FALSE)=0, "", VLOOKUP($G16, SeanRanks!$A$2:$H$303, 7, FALSE)) -> 12
B17: =IFERROR(INT(AVERAGE(Q17:U17)/12)+1, INT(AVERAGE(M17)/12)+1) -> 1 | C17: No | D17: 2 | F17: =VLOOKUP(G17, SeanRanks!$A$2:$E$302, 4, FALSE) -> 0 | G17: Puka Nacua | H17: =VLOOKUP($G17, 'ADP Data'!$C$4:$Q$300, 2, FALSE) -> LAR | I17: =VLOOKUP(G17, 'ADP Data'!$C$4:$R$498, 12, FALSE) -> 13 | J17: =VLOOKUP($G17, SeanRanks!$A$2:$H$303, 5, FALSE) -> 0 | K17: =IF(VLOOKUP($G17, SeanRanks!$A$2:$H$303, 6, FALSE)=0, "", VLOOKUP($G17, SeanRanks!$A$2:$H$303, 6, FALSE)) -> WR1 - 2 - High Floor | L17: =IFERROR(INT(M17/8)+1, 16) -> 2 | M17: =VLOOKUP($G17, 'ADP Data'!$C$4:$Q$300, 9, FALSE) -> 11 | N17: =M17-V17 -> 0 | O17: =VLOOKUP($G17, 'ADP Data'!$C$4:$Q$300, 3, FALSE) -> 14 | P17: =M17-O17 -> -3 | Q17: =VLOOKUP($G17, 'ADP Data'!$C$4:$Q$300, 4, FALSE) -> 9 | R17: =VLOOKUP($G17, 'ADP Data'!$C$4:$Q$300, 5, FALSE) -> 8 | S17: =VLOOKUP($G17, 'ADP Data'!$C$4:$Q$300, 6, FALSE) -> 15 | T17: =VLOOKUP($G17, 'ADP Data'!$C$4:$Q$300, 7, FALSE) -> 14 | U17: =VLOOKUP($G17, 'ADP Data'!$C$4:$Q$300, 8, FALSE) -> 7 | V17: =INT(AVERAGE(M17, O17,Q17:U17)) -> 11 | W17: =IFERROR(INT(V17/8)+1, 16) -> 2 | X17: =D17-W17 -> 0 | Y17: =VLOOKUP($G17, SeanRanks!$A$2:$K$303, 10, FALSE)-V17 -> 5 | Z17: =IF(VLOOKUP($G17, SeanRanks!$A$2:$H$303, 7, FALSE)=0, "", VLOOKUP($G17, SeanRanks!$A$2:$H$303, 7, FALSE)) -> 9
B18: =IFERROR(INT(AVERAGE(Q18:U18)/12)+1, INT(AVERAGE(M18)/12)+1) -> 4 | C18: No | F18: =VLOOKUP(G18, SeanRanks!$A$2:$E$302, 4, FALSE) -> 0 | G18: Garrett Wilson | H18: =VLOOKUP($G18, 'ADP Data'!$C$4:$Q$300, 2, FALSE) -> NYJ | I18: =VLOOKUP(G18, 'ADP Data'!$C$4:$R$498, 12, FALSE) -> 28 | J18: =VLOOKUP($G18, SeanRanks!$A$2:$H$303, 5, FALSE) -> 0 | K18: =IF(VLOOKUP($G18, SeanRanks!$A$2:$H$303, 6, FALSE)=0, "", VLOOKUP($G18, SeanRanks!$A$2:$H$303, 6, FALSE)) -> WR2 - 1 - WR1 upside | L18: =IFERROR(INT(M18/8)+1, 16) -> 5 | M18: =VLOOKUP($G18, 'ADP Data'!$C$4:$Q$300, 9, FALSE) -> 34 | N18: =M18-V18 -> -4 | O18: =VLOOKUP($G18, 'ADP Data'!$C$4:$Q$300, 3, FALSE) -> 51 | P18: =M18-O18 -> -17 | Q18: =VLOOKUP($G18, 'ADP Data'!$C$4:$Q$300, 4, FALSE) -> 41 | R18: =VLOOKUP($G18, 'ADP Data'!$C$4:$Q$300, 5, FALSE) -> 37 | S18: =VLOOKUP($G18, 'ADP Data'!$C$4:$Q$300, 6, FALSE) -> 39 | T18: =VLOOKUP($G18, 'ADP Data'!$C$4:$Q$300, 7, FALSE) -> 30 | U18: =VLOOKUP($G18, 'ADP Data'!$C$4:$Q$300, 8, FALSE) -> 37 | V18: =INT(AVERAGE(M18, O18,Q18:U18)) -> 38 | W18: =IFERROR(INT(V18/8)+1, 16) -> 5 | X18: =D18-W18 -> -5 | Y18: =VLOOKUP($G18, SeanRanks!$A$2:$K$303, 10, FALSE)-V18 -> 1 | Z18: =IF(VLOOKUP($G18, SeanRanks!$A$2:$H$303, 7, FALSE)=0, "", VLOOKUP($G18, SeanRanks!$A$2:$H$303, 7, FALSE)) -> 17
B19: =IFERROR(INT(AVERAGE(Q19:U19)/12)+1, INT(AVERAGE(M19)/12)+1) -> 1 | C19: No | D19: 2 | F19: =VLOOKUP(G19, SeanRanks!$A$2:$E$302, 4, FALSE) -> 0 | G19: Saquon Barkley | H19: =VLOOKUP($G19, 'ADP Data'!$C$4:$Q$300, 2, FALSE) -> PHI | I19: =VLOOKUP(G19, 'ADP Data'!$C$4:$R$498, 12, FALSE) -> 6 | J19: =VLOOKUP($G19, SeanRanks!$A$2:$H$303, 5, FALSE) -> 0 | K19: =IF(VLOOKUP($G19, SeanRanks!$A$2:$H$303, 6, FALSE)=0, "", VLOOKUP($G19, SeanRanks!$A$2:$H$303, 6, FALSE)) -> RB1 - 1 - Elite floor/ceiling | L19: =IFERROR(INT(M19/8)+1, 16) -> 1 | M19: =VLOOKUP($G19, 'ADP Data'!$C$4:$Q$300, 9, FALSE) -> 2 | N19: =M19-V19 -> -2 | O19: =VLOOKUP($G19, 'ADP Data'!$C$4:$Q$300, 3, FALSE) -> 3 | P19: =M19-O19 -> -1 | Q19: =VLOOKUP($G19, 'ADP Data'!$C$4:$Q$300, 4, FALSE) -> 3 | R19: =VLOOKUP($G19, 'ADP Data'!$C$4:$Q$300, 5, FALSE) -> 6 | S19: =VLOOKUP($G19, 'ADP Data'!$C$4:$Q$300, 6, FALSE) -> 5 | T19: =VLOOKUP($G19, 'ADP Data'!$C$4:$Q$300, 7, FALSE) -> 5 | U19: =VLOOKUP($G19, 'ADP Data'!$C$4:$Q$300, 8, FALSE) -> 4 | V19: =INT(AVERAGE(M19, O19,Q19:U19)) -> 4 | W19: =IFERROR(INT(V19/8)+1, 16) -> 1 | X19: =D19-W19 -> 1 | Y19: =VLOOKUP($G19, SeanRanks!$A$2:$K$303, 10, FALSE)-V19 -> -1 | Z19: =IF(VLOOKUP($G19, SeanRanks!$A$2:$H$303, 7, FALSE)=0, "", VLOOKUP($G19, SeanRanks!$A$2:$H$303, 7, FALSE)) -> 2
B20: =IFERROR(INT(AVERAGE(Q20:U20)/12)+1, INT(AVERAGE(M20)/12)+1) -> 1 | C20: No | D20: 2 | F20: =VLOOKUP(G20, SeanRanks!$A$2:$E$302, 4, FALSE) -> 0 | G20: Jahmyr Gibbs | H20: =VLOOKUP($G20, 'ADP Data'!$C$4:$Q$300, 2, FALSE) -> DET | I20: =VLOOKUP(G20, 'ADP Data'!$C$4:$R$498, 12, FALSE) -> 4 | J20: =VLOOKUP($G20, SeanRanks!$A$2:$H$303, 5, FALSE) -> 0 | K20: =IF(VLOOKUP($G20, SeanRanks!$A$2:$H$303, 6, FALSE)=0, "", VLOOKUP($G20, SeanRanks!$A$2:$H$303, 6, FALSE)) -> RB1 - 1 - Elite floor/ceiling | L20: =IFERROR(INT(M20/8)+1, 16) -> 1 | M20: =VLOOKUP($G20, 'ADP Data'!$C$4:$Q$300, 9, FALSE) -> 4 | N20: =M20-V20 -> 0 | O20: =VLOOKUP($G20, 'ADP Data'!$C$4:$Q$300, 3, FALSE) -> 4 | P20: =M20-O20 -> 0 | Q20: =VLOOKUP($G20, 'ADP Data'!$C$4:$Q$300, 4, FALSE) -> 5 | R20: =VLOOKUP($G20, 'ADP Data'!$C$4:$Q$300, 5, FALSE) -> 4 | S20: =VLOOKUP($G20, 'ADP Data'!$C$4:$Q$300, 6, FALSE) -> 3 | T20: =VLOOKUP($G20, 'ADP Data'!$C$4:$Q$300, 7, FALSE) -> 3 | U20: =VLOOKUP($G20, 'ADP Data'!$C$4:$Q$300, 8, FALSE) -> 6 | V20: =INT(AVERAGE(M20, O20,Q20:U20)) -> 4 | W20: =IFERROR(INT(V20/8)+1, 16) -> 1 | X20: =D20-W20 -> 1 | Y20: =VLOOKUP($G20, SeanRanks!$A$2:$K$303, 10, FALSE)-V20 -> 0 | Z20: =IF(VLOOKUP($G20, SeanRanks!$A$2:$H$303, 7, FALSE)=0, "", VLOOKUP($G20, SeanRanks!$A$2:$H$303, 7, FALSE)) -> 3
B21: =IFERROR(INT(AVERAGE(Q21:U21)/12)+1, INT(AVERAGE(M21)/12)+1) -> 4 | C21: No | D21: 2 | F21: =VLOOKUP(G21, SeanRanks!$A$2:$E$302, 4, FALSE) -> 0 | G21: Marvin Harrison Jr. | H21: =VLOOKUP($G21, 'ADP Data'!$C$4:$Q$300, 2, FALSE) -> ARI | I21: =VLOOKUP(G21, 'ADP Data'!$C$4:$R$498, 12, FALSE) -> 37 | J21: =VLOOKUP($G21, SeanRanks!$A$2:$H$303, 5, FALSE) -> Yes | K21: =IF(VLOOKUP($G21, SeanRanks!$A$2:$H$303, 6, FALSE)=0, "", VLOOKUP($G21, SeanRanks!$A$2:$H$303, 6, FALSE)) -> WR2 - 1 - WR1 upside | L21: =IFERROR(INT(M21/8)+1, 16) -> 5 | M21: =VLOOKUP($G21, 'ADP Data'!$C$4:$Q$300, 9, FALSE) -> 36 | N21: =M21-V21 -> -4 | O21: =VLOOKUP($G21, 'ADP Data'!$C$4:$Q$300, 3, FALSE) -> 46 | P21: =M21-O21 -> -10 | Q21: =VLOOKUP($G21, 'ADP Data'!$C$4:$Q$300, 4, FALSE) -> 44 | R21: =VLOOKUP($G21, 'ADP Data'!$C$4:$Q$300, 5, FALSE) -> 39 | S21: =VLOOKUP($G21, 'ADP Data'!$C$4:$Q$300, 6, FALSE) -> 41 | T21: =VLOOKUP($G21, 'ADP Data'!$C$4:$Q$300, 7, FALSE) -> 34 | U21: =VLOOKUP($G21, 'ADP Data'!$C$4:$Q$300, 8, FALSE) -> 41 | V21: =INT(AVERAGE(M21, O21,Q21:U21)) -> 40 | W21: =IFERROR(INT(V21/8)+1, 16) -> 6 | X21: =D21-W21 -> -4 | Y21: =VLOOKUP($G21, SeanRanks!$A$2:$K$303, 10, FALSE)-V21 -> -3 | Z21: =IF(VLOOKUP($G21, SeanRanks!$A$2:$H$303, 7, FALSE)=0, "", VLOOKUP($G21, SeanRanks!$A$2:$H$303, 7, FALSE)) -> 14
A22: Yes | B22: =IFERROR(INT(AVERAGE(Q22:U22)/12)+1, INT(AVERAGE(M22)/12)+1) -> 3 | C22: No | D22: 2 | F22: =VLOOKUP(G22, SeanRanks!$A$2:$E$302, 4, FALSE) -> 0 | G22: Kyren Williams | H22: =VLOOKUP($G22, 'ADP Data'!$C$4:$Q$300, 2, FALSE) -> LAR | I22: =VLOOKUP(G22, 'ADP Data'!$C$4:$R$498, 12, FALSE) -> 31 | J22: =VLOOKUP($G22, SeanRanks!$A$2:$H$303, 5, FALSE) -> 0 | K22: =IF(VLOOKUP($G22, SeanRanks!$A$2:$H$303, 6, FALSE)=0, "", VLOOKUP($G22, SeanRanks!$A$2:$H$303, 6, FALSE)) -> RB1 - 2 - Elite ceiling/questions | L22: =IFERROR(INT(M22/8)+1, 16) -> 4 | M22: =VLOOKUP($G22, 'ADP Data'!$C$4:$Q$300, 9, FALSE) -> 25 | N22: =M22-V22 -> 0 | O22: =VLOOKUP($G22, 'ADP Data'!$C$4:$Q$300, 3, FALSE) -> 18 | P22: =M22-O22 -> 7 | Q22: =VLOOKUP($G22, 'ADP Data'!$C$4:$Q$300, 4, FALSE) -> 29 | R22: =VLOOKUP($G22, 'ADP Data'!$C$4:$Q$300, 5, FALSE) -> 30 | S22: =VLOOKUP($G22, 'ADP Data'!$C$4:$Q$300, 6, FALSE) -> 26 | T22: =VLOOKUP($G22, 'ADP Data'!$C$4:$Q$300, 7, FALSE) -> 27 | U22: =VLOOKUP($G22, 'ADP Data'!$C$4:$Q$300, 8, FALSE) -> 25 | V22: =INT(AVERAGE(M22, O22,Q22:U22)) -> 25 | W22: =IFERROR(INT(V22/8)+1, 16) -> 4 | X22: =D22-W22 -> -2 | Y22: =VLOOKUP($G22, SeanRanks!$A$2:$K$303, 10, FALSE)-V22 -> 2 | Z22: =IF(VLOOKUP($G22, SeanRanks!$A$2:$H$303, 7, FALSE)=0, "", VLOOKUP($G22, SeanRanks!$A$2:$H$303, 7, FALSE)) -> 11
B23: =IFERROR(INT(AVERAGE(Q23:U23)/12)+1, INT(AVERAGE(M23)/12)+1) -> 2 | C23: No | D23: 2 | F23: =VLOOKUP(G23, SeanRanks!$A$2:$E$302, 4, FALSE) -> 0 | G23: Derrick Henry | H23: =VLOOKUP($G23, 'ADP Data'!$C$4:$Q$300, 2, FALSE) -> BAL | I23: =VLOOKUP(G23, 'ADP Data'!$C$4:$R$498, 12, FALSE) -> 15 | J23: =VLOOKUP($G23, SeanRanks!$A$2:$H$303, 5, FALSE) -> 0 | K23: =IF(VLOOKUP($G23, SeanRanks!$A$2:$H$303, 6, FALSE)=0, "", VLOOKUP($G23, SeanRanks!$A$2:$H$303, 6, FALSE)) -> RB1 - 2 - Elite ceiling/questions | L23: =IFERROR(INT(M23/8)+1, 16) -> 1 | M23: =VLOOKUP($G23, 'ADP Data'!$C$4:$Q$300, 9, FALSE) -> 7 | N23: =M23-V23 -> -3 | O23: =VLOOKUP($G23, 'ADP Data'!$C$4:$Q$300, 3, FALSE) -> 7 | P23: =M23-O23 -> 0 | Q23: =VLOOKUP($G23, 'ADP Data'!$C$4:$Q$300, 4, FALSE) -> 12 | R23: =VLOOKUP($G23, 'ADP Data'!$C$4:$Q$300, 5, FALSE) -> 13 | S23: =VLOOKUP($G23, 'ADP Data'!$C$4:$Q$300, 6, FALSE) -> 14 | T23: =VLOOKUP($G23, 'ADP Data'!$C$4:$Q$300, 7, FALSE) -> 13 | U23: =VLOOKUP($G23, 'ADP Data'!$C$4:$Q$300, 8, FALSE) -> 10 | V23: =INT(AVERAGE(M23, O23,Q23:U23)) -> 10 | W23: =IFERROR(INT(V23/8)+1, 16) -> 2 | X23: =D23-W23 -> 0 | Y23: =VLOOKUP($G23, SeanRanks!$A$2:$K$303, 10, FALSE)-V23 -> 1 | Z23: =IF(VLOOKUP($G23, SeanRanks!$A$2:$H$303, 7, FALSE)=0, "", VLOOKUP($G23, SeanRanks!$A$2:$H$303, 7, FALSE)) -> 8
B24: =IFERROR(INT(AVERAGE(Q24:U24)/12)+1, INT(AVERAGE(M24)/12)+1) -> 7 | C24: No | F24: =VLOOKUP(G24, SeanRanks!$A$2:$E$302, 4, FALSE) -> 0 | G24: Chris Olave | H24: =VLOOKUP($G24, 'ADP Data'!$C$4:$Q$300, 2, FALSE) -> NO | I24: =VLOOKUP(G24, 'ADP Data'!$C$4:$R$498, 12, FALSE) -> 71 | J24: =VLOOKUP($G24, SeanRanks!$A$2:$H$303, 5, FALSE) -> 0 | K24: =IF(VLOOKUP($G24, SeanRanks!$A$2:$H$303, 6, FALSE)=0, "", VLOOKUP($G24, SeanRanks!$A$2:$H$303, 6, FALSE)) -> WR3 - 2 - mid, but path to big upside | L24: =IFERROR(INT(M24/8)+1, 16) -> 10 | M24: =VLOOKUP($G24, 'ADP Data'!$C$4:$Q$300, 9, FALSE) -> 73 | N24: =M24-V24 -> -9 | O24: =VLOOKUP($G24, 'ADP Data'!$C$4:$Q$300, 3, FALSE) -> 101 | P24: =M24-O24 -> -28 | Q24: =VLOOKUP($G24, 'ADP Data'!$C$4:$Q$300, 4, FALSE) -> 84 | R24: =VLOOKUP($G24, 'ADP Data'!$C$4:$Q$300, 5, FALSE) -> 78 | S24: =VLOOKUP($G24, 'ADP Data'!$C$4:$Q$300, 6, FALSE) -> 82 | T24: =VLOOKUP($G24, 'ADP Data'!$C$4:$Q$300, 7, FALSE) -> 72 | U24: =VLOOKUP($G24, 'ADP Data'!$C$4:$Q$300, 8, FALSE) -> 87 | V24: =INT(AVERAGE(M24, O24,Q24:U24)) -> 82 | W24: =IFERROR(INT(V24/8)+1, 16) -> 11 | X24: =D24-W24 -> -11 | Y24: =VLOOKUP($G24, SeanRanks!$A$2:$K$303, 10, FALSE)-V24 -> -16 | Z24: =IF(VLOOKUP($G24, SeanRanks!$A$2:$H$303, 7, FALSE)=0, "", VLOOKUP($G24, SeanRanks!$A$2:$H$303, 7, FALSE)) -> 32
B25: =IFERROR(INT(AVERAGE(Q25:U25)/12)+1, INT(AVERAGE(M25)/12)+1) -> 6 | C25: No | D25: 2 | F25: =VLOOKUP(G25, SeanRanks!$A$2:$E$302, 4, FALSE) -> 0 | G25: Isiah Pacheco | H25: =VLOOKUP($G25, 'ADP Data'!$C$4:$Q$300, 2, FALSE) -> KC | I25: =VLOOKUP(G25, 'ADP Data'!$C$4:$R$498, 12, FALSE) -> 68 | J25: =VLOOKUP($G25, SeanRanks!$A$2:$H$303, 5, FALSE) -> 0 | K25: =IF(VLOOKUP($G25, SeanRanks!$A$2:$H$303, 6, FALSE)=0, "", VLOOKUP($G25, SeanRanks!$A$2:$H$303, 6, FALSE)) -> RB2 - 2 - Path to spikes | L25: =IFERROR(INT(M25/8)+1, 16) -> 8 | M25: =VLOOKUP($G25, 'ADP Data'!$C$4:$Q$300, 9, FALSE) -> 61 | N25: =M25-V25 -> -4 | O25: =VLOOKUP($G25, 'ADP Data'!$C$4:$Q$300, 3, FALSE) -> 66 | P25: =M25-O25 -> -5 | Q25: =VLOOKUP($G25, 'ADP Data'!$C$4:$Q$300, 4, FALSE) -> 63 | R25: =VLOOKUP($G25, 'ADP Data'!$C$4:$Q$300, 5, FALSE) -> 77 | S25: =VLOOKUP($G25, 'ADP Data'!$C$4:$Q$300, 6, FALSE) -> 62 | T25: =VLOOKUP($G25, 'ADP Data'!$C$4:$Q$300, 7, FALSE) -> 67 | U25: =VLOOKUP($G25, 'ADP Data'!$C$4:$Q$300, 8, FALSE) -> 59 | V25: =INT(AVERAGE(M25, O25,Q25:U25)) -> 65 | W25: =IFERROR(INT(V25/8)+1, 16) -> 9 | X25: =D25-W25 -> -7 | Y25: =VLOOKUP($G25, SeanRanks!$A$2:$K$303, 10, FALSE)-V25 -> 0 | Z25: =IF(VLOOKUP($G25, SeanRanks!$A$2:$H$303, 7, FALSE)=0, "", VLOOKUP($G25, SeanRanks!$A$2:$H$303, 7, FALSE)) -> 23
B26: =IFERROR(INT(AVERAGE(Q26:U26)/12)+1, INT(AVERAGE(M26)/12)+1) -> 4 | C26: No | D26: 2 | F26: =VLOOKUP(G26, SeanRanks!$A$2:$E$302, 4, FALSE) -> 0 | G26: Davante Adams | H26: =VLOOKUP($G26, 'ADP Data'!$C$4:$Q$300, 2, FALSE) -> LAR | I26: =VLOOKUP(G26, 'ADP Data'!$C$4:$R$498, 12, FALSE) -> 41 | J26: =VLOOKUP($G26, SeanRanks!$A$2:$H$303, 5, FALSE) -> 0 | K26: =IF(VLOOKUP($G26, SeanRanks!$A$2:$H$303, 6, FALSE)=0, "", VLOOKUP($G26, SeanRanks!$A$2:$H$303, 6, FALSE)) -> WR2 - 2 - Upside with risk | L26: =IFERROR(INT(M26/8)+1, 16) -> 6 | M26: =VLOOKUP($G26, 'ADP Data'!$C$4:$Q$300, 9, FALSE) -> 44 | N26: =M26-V26 -> 3 | O26: =VLOOKUP($G26, 'ADP Data'!$C$4:$Q$300, 3, FALSE) -> 34 | P26: =M26-O26 -> 10 | Q26: =VLOOKUP($G26, 'ADP Data'!$C$4:$Q$300, 4, FALSE) -> 34 | R26: =VLOOKUP($G26, 'ADP Data'!$C$4:$Q$300, 5, FALSE) -> 47 | S26: =VLOOKUP($G26, 'ADP Data'!$C$4:$Q$300, 6, FALSE) -> 43 | T26: =VLOOKUP($G26, 'ADP Data'!$C$4:$Q$300, 7, FALSE) -> 37 | U26: =VLOOKUP($G26, 'ADP Data'!$C$4:$Q$300, 8, FALSE) -> 48 | V26: =INT(AVERAGE(M26, O26,Q26:U26)) -> 41 | W26: =IFERROR(INT(V26/8)+1, 16) -> 6 | X26: =D26-W26 -> -4 | Y26: =VLOOKUP($G26, SeanRanks!$A$2:$K$303, 10, FALSE)-V26 -> 2 | Z26: =IF(VLOOKUP($G26, SeanRanks!$A$2:$H$303, 7, FALSE)=0, "", VLOOKUP($G26, SeanRanks!$A$2:$H$303, 7, FALSE)) -> 19
B27: =IFERROR(INT(AVERAGE(Q27:U27)/12)+1, INT(AVERAGE(M27)/12)+1) -> 9 | C27: No | D27: 2 | F27: =VLOOKUP(G27, SeanRanks!$A$2:$E$302, 4, FALSE) -> 0 | G27: Travis Etienne | H27: =VLOOKUP($G27, 'ADP Data'!$C$4:$Q$300, 2, FALSE) -> JAX | I27: =VLOOKUP(G27, 'ADP Data'!$C$4:$R$498, 12, FALSE) -> 101 | J27: =VLOOKUP($G27, SeanRanks!$A$2:$H$303, 5, FALSE) -> 0 | K27: =IF(VLOOKUP($G27, SeanRanks!$A$2:$H$303, 6, FALSE)=0, "", VLOOKUP($G27, SeanRanks!$A$2:$H$303, 6, FALSE)) -> RB3 - 2 - low ceiling | L27: =IFERROR(INT(M27/8)+1, 16) -> 11 | M27: =VLOOKUP($G27, 'ADP Data'!$C$4:$Q$300, 9, FALSE) -> 85 | N27: =M27-V27 -> -14 | O27: =VLOOKUP($G27, 'ADP Data'!$C$4:$Q$300, 3, FALSE) -> 90 | P27: =M27-O27 -> -5 | Q27: =VLOOKUP($G27, 'ADP Data'!$C$4:$Q$300, 4, FALSE) -> 116 | R27: =VLOOKUP($G27, 'ADP Data'!$C$4:$Q$300, 5, FALSE) -> 102 | S27: =VLOOKUP($G27, 'ADP Data'!$C$4:$Q$300, 6, FALSE) -> 94 | T27: =VLOOKUP($G27, 'ADP Data'!$C$4:$Q$300, 7, FALSE) -> 90 | U27: =VLOOKUP($G27, 'ADP Data'!$C$4:$Q$300, 8, FALSE) -> 121 | V27: =INT(AVERAGE(M27, O27,Q27:U27)) -> 99 | W27: =IFERROR(INT(V27/8)+1, 16) -> 13 | X27: =D27-W27 -> -11 | Y27: =VLOOKUP($G27, SeanRanks!$A$2:$K$303, 10, FALSE)-V27 -> -3 | Z27: =IF(VLOOKUP($G27, SeanRanks!$A$2:$H$303, 7, FALSE)=0, "", VLOOKUP($G27, SeanRanks!$A$2:$H$303, 7, FALSE)) -> 33
A28: Yes | B28: =IFERROR(INT(AVERAGE(Q28:U28)/12)+1, INT(AVERAGE(M28)/12)+1) -> 2 | C28: No | F28: =VLOOKUP(G28, SeanRanks!$A$2:$E$302, 4, FALSE) -> 0 | G28: Drake London | H28: =VLOOKUP($G28, 'ADP Data'!$C$4:$Q$300, 2, FALSE) -> ATL | I28: =VLOOKUP(G28, 'ADP Data'!$C$4:$R$498, 12, FALSE) -> 14 | J28: =VLOOKUP($G28, SeanRanks!$A$2:$H$303, 5, FALSE) -> 0 | K28: =IF(VLOOKUP($G28, SeanRanks!$A$2:$H$303, 6, FALSE)=0, "", VLOOKUP($G28, SeanRanks!$A$2:$H$303, 6, FALSE)) -> WR1 - 2 - High Floor | L28: =IFERROR(INT(M28/8)+1, 16) -> 3 | M28: =VLOOKUP($G28, 'ADP Data'!$C$4:$Q$300, 9, FALSE) -> 17 | N28: =M28-V28 -> -1 | O28: =VLOOKUP($G28, 'ADP Data'!$C$4:$Q$300, 3, FALSE) -> 23 | P28: =M28-O28 -> -6 | Q28: =VLOOKUP($G28, 'ADP Data'!$C$4:$Q$300, 4, FALSE) -> 21 | R28: =VLOOKUP($G28, 'ADP Data'!$C$4:$Q$300, 5, FALSE) -> 16 | S28: =VLOOKUP($G28, 'ADP Data'!$C$4:$Q$300, 6, FALSE) -> 19 | T28: =VLOOKUP($G28, 'ADP Data'!$C$4:$Q$300, 7, FALSE) -> 15 | U28: =VLOOKUP($G28, 'ADP Data'!$C$4:$Q$300, 8, FALSE) -> 20 | V28: =INT(AVERAGE(M28, O28,Q28:U28)) -> 18 | W28: =IFERROR(INT(V28/8)+1, 16) -> 3 | X28: =D28-W28 -> -3 | Y28: =VLOOKUP($G28, SeanRanks!$A$2:$K$303, 10, FALSE)-V28 -> -6 | Z28: =IF(VLOOKUP($G28, SeanRanks!$A$2:$H$303, 7, FALSE)=0, "", VLOOKUP($G28, SeanRanks!$A$2:$H$303, 7, FALSE)) -> 7
B29: =IFERROR(INT(AVERAGE(Q29:U29)/12)+1, INT(AVERAGE(M29)/12)+1) -> 2 | C29: No | F29: =VLOOKUP(G29, SeanRanks!$A$2:$E$302, 4, FALSE) -> 0 | G29: De'Von Achane | H29: =VLOOKUP($G29, 'ADP Data'!$C$4:$Q$300, 2, FALSE) -> MIA | I29: =VLOOKUP(G29, 'ADP Data'!$C$4:$R$498, 12, FALSE) -> 18 | J29: =VLOOKUP($G29, SeanRanks!$A$2:$H$303, 5, FALSE) -> 0 | K29: =IF(VLOOKUP($G29, SeanRanks!$A$2:$H$303, 6, FALSE)=0, "", VLOOKUP($G29, SeanRanks!$A$2:$H$303, 6, FALSE)) -> RB1 - 2 - Elite ceiling/questions | L29: =IFERROR(INT(M29/8)+1, 16) -> 2 | M29: =VLOOKUP($G29, 'ADP Data'!$C$4:$Q$300, 9, FALSE) -> 14 | N29: =M29-V29 -> -1 | O29: =VLOOKUP($G29, 'ADP Data'!$C$4:$Q$300, 3, FALSE) -> 16 | P29: =M29-O29 -> -2 | Q29: =VLOOKUP($G29, 'ADP Data'!$C$4:$Q$300, 4, FALSE) -> 14 | R29: =VLOOKUP($G29, 'ADP Data'!$C$4:$Q$300, 5, FALSE) -> 15 | S29: =VLOOKUP($G29, 'ADP Data'!$C$4:$Q$300, 6, FALSE) -> 18 | T29: =VLOOKUP($G29, 'ADP Data'!$C$4:$Q$300, 7, FALSE) -> 16 | U29: =VLOOKUP($G29, 'ADP Data'!$C$4:$Q$300, 8, FALSE) -> 14 | V29: =INT(AVERAGE(M29, O29,Q29:U29)) -> 15 | W29: =IFERROR(INT(V29/8)+1, 16) -> 2 | X29: =D29-W29 -> -2 | Y29: =VLOOKUP($G29, SeanRanks!$A$2:$K$303, 10, FALSE)-V29 -> 5 | Z29: =IF(VLOOKUP($G29, SeanRanks!$A$2:$H$303, 7, FALSE)=0, "", VLOOKUP($G29, SeanRanks!$A$2:$H$303, 7, FALSE)) -> 6
A30: Yes | B30: =IFERROR(INT(AVERAGE(Q30:U30)/12)+1, INT(AVERAGE(M30)/12)+1) -> 6 | C30: No | D30: 3 | F30: =VLOOKUP(G30, SeanRanks!$A$2:$E$302, 4, FALSE) -> 0 | G30: Travis Kelce | H30: =VLOOKUP($G30, 'ADP Data'!$C$4:$Q$300, 2, FALSE) -> KC | I30: =VLOOKUP(G30, 'ADP Data'!$C$4:$R$498, 12, FALSE) -> 79 | J30: =VLOOKUP($G30, SeanRanks!$A$2:$H$303, 5, FALSE) -> No | K30: =IF(VLOOKUP($G30, SeanRanks!$A$2:$H$303, 6, FALSE)=0, "", VLOOKUP($G30, SeanRanks!$A$2:$H$303, 6, FALSE)) -> TE1 - 3 - Weekly Start | L30: =IFERROR(INT(M30/8)+1, 16) -> 9 | M30: =VLOOKUP($G30, 'ADP Data'!$C$4:$Q$300, 9, FALSE) -> 67 | N30: =M30-V30 -> -1 | O30: =VLOOKUP($G30, 'ADP Data'!$C$4:$Q$300, 3, FALSE) -> 61 | P30: =M30-O30 -> 6 | Q30: =VLOOKUP($G30, 'ADP Data'!$C$4:$Q$300, 4, FALSE) -> 57 | R30: =VLOOKUP($G30, 'ADP Data'!$C$4:$Q$300, 5, FALSE) -> 88 | S30: =VLOOKUP($G30, 'ADP Data'!$C$4:$Q$300, 6, FALSE) -> 63 | T30: =VLOOKUP($G30, 'ADP Data'!$C$4:$Q$300, 7, FALSE) -> 82 | U30: =VLOOKUP($G30, 'ADP Data'!$C$4:$Q$300, 8, FALSE) -> 58 | V30: =INT(AVERAGE(M30, O30,Q30:U30)) -> 68 | W30: =IFERROR(INT(V30/8)+1, 16) -> 9 | X30: =D30-W30 -> -6 | Y30: =VLOOKUP($G30, SeanRanks!$A$2:$K$303, 10, FALSE)-V30 -> 14 | Z30: =IF(VLOOKUP($G30, SeanRanks!$A$2:$H$303, 7, FALSE)=0, "", VLOOKUP($G30, SeanRanks!$A$2:$H$303, 7, FALSE)) -> 9
B31: =IFERROR(INT(AVERAGE(Q31:U31)/12)+1, INT(AVERAGE(M31)/12)+1) -> 8 | C31: No | D31: 2 | F31: =VLOOKUP(G31, SeanRanks!$A$2:$E$302, 4, FALSE) -> 0 | G31: Deebo Samuel | H31: =VLOOKUP($G31, 'ADP Data'!$C$4:$Q$300, 2, FALSE) -> WAS | I31: =VLOOKUP(G31, 'ADP Data'!$C$4:$R$498, 12, FALSE) -> 69 | J31: =VLOOKUP($G31, SeanRanks!$A$2:$H$303, 5, FALSE) -> Yes | K31: =IF(VLOOKUP($G31, SeanRanks!$A$2:$H$303, 6, FALSE)=0, "", VLOOKUP($G31, SeanRanks!$A$2:$H$303, 6, FALSE)) -> WR4 - 1 - path to WR2 | L31: =IFERROR(INT(M31/8)+1, 16) -> 11 | M31: =VLOOKUP($G31, 'ADP Data'!$C$4:$Q$300, 9, FALSE) -> 84 | N31: =M31-V31 -> 0 | O31: =VLOOKUP($G31, 'ADP Data'!$C$4:$Q$300, 3, FALSE) -> 75 | P31: =M31-O31 -> 9 | Q31: =VLOOKUP($G31, 'ADP Data'!$C$4:$Q$300, 4, FALSE) -> 95 | R31: =VLOOKUP($G31, 'ADP Data'!$C$4:$Q$300, 5, FALSE) -> 83 | S31: =VLOOKUP($G31, 'ADP Data'!$C$4:$Q$300, 6, FALSE) -> 83 | T31: =VLOOKUP($G31, 'ADP Data'!$C$4:$Q$300, 7, FALSE) -> 75 | U31: =VLOOKUP($G31, 'ADP Data'!$C$4:$Q$300, 8, FALSE) -> 96 | V31: =INT(AVERAGE(M31, O31,Q31:U31)) -> 84 | W31: =IFERROR(INT(V31/8)+1, 16) -> 11 | X31: =D31-W31 -> -9 | Y31: =VLOOKUP($G31, SeanRanks!$A$2:$K$303, 10, FALSE)-V31 -> 10 | Z31: =IF(VLOOKUP($G31, SeanRanks!$A$2:$H$303, 7, FALSE)=0, "", VLOOKUP($G31, SeanRanks!$A$2:$H$303, 7, FALSE)) -> 41
B32: =IFERROR(INT(AVERAGE(Q32:U32)/12)+1, INT(AVERAGE(M32)/12)+1) -> 2 | C32: No | D32: 4 | F32: =VLOOKUP(G32, SeanRanks!$A$2:$E$302, 4, FALSE) -> 0 | G32: Josh Allen | H32: =VLOOKUP($G32, 'ADP Data'!$C$4:$Q$300, 2, FALSE) -> BUF | I32: =VLOOKUP(G32, 'ADP Data'!$C$4:$R$498, 12, FALSE) -> 26 | J32: =VLOOKUP($G32, SeanRanks!$A$2:$H$303, 5, FALSE) -> 0 | K32: =IF(VLOOKUP($G32, SeanRanks!$A$2:$H$303, 6, FALSE)=0, "", VLOOKUP($G32, SeanRanks!$A$2:$H$303, 6, FALSE)) -> QB1 - 1 - Elite | L32: =IFERROR(INT(M32/8)+1, 16) -> 3 | M32: =VLOOKUP($G32, 'ADP Data'!$C$4:$Q$300, 9, FALSE) -> 21 | N32: =M32-V32 -> -1 | O32: =VLOOKUP($G32, 'ADP Data'!$C$4:$Q$300, 3, FALSE) -> 15 | P32: =M32-O32 -> 6 | Q32: =VLOOKUP($G32, 'ADP Data'!$C$4:$Q$300, 4, FALSE) -> 19 | R32: =VLOOKUP($G32, 'ADP Data'!$C$4:$Q$300, 5, FALSE) -> 27 | S32: =VLOOKUP($G32, 'ADP Data'!$C$4:$Q$300, 6, FALSE) -> 27 | T32: =VLOOKUP($G32, 'ADP Data'!$C$4:$Q$300, 7, FALSE) -> 25 | U32: =VLOOKUP($G32, 'ADP Data'!$C$4:$Q$300, 8, FALSE) -> 21 | V32: =INT(AVERAGE(M32, O32,Q32:U32)) -> 22 | W32: =IFERROR(INT(V32/8)+1, 16) -> 3 | X32: =D32-W32 -> 1 | Y32: =VLOOKUP($G32, SeanRanks!$A$2:$K$303, 10, FALSE)-V32 -> 6 | Z32: =IF(VLOOKUP($G32, SeanRanks!$A$2:$H$303, 7, FALSE)=0, "", VLOOKUP($G32, SeanRanks!$A$2:$H$303, 7, FALSE)) -> 2
B33: =IFERROR(INT(AVERAGE(Q33:U33)/12)+1, INT(AVERAGE(M33)/12)+1) -> 4 | C33: No | D33: 2 | F33: =VLOOKUP(G33, SeanRanks!$A$2:$E$302, 4, FALSE) -> 0 | G33: Mike Evans | H33: =VLOOKUP($G33, 'ADP Data'!$C$4:$Q$300, 2, FALSE) -> TB | I33: =VLOOKUP(G33, 'ADP Data'!$C$4:$R$498, 12, FALSE) -> 32 | J33: =VLOOKUP($G33, SeanRanks!$A$2:$H$303, 5, FALSE) -> 0 | K33: =IF(VLOOKUP($G33, SeanRanks!$A$2:$H$303, 6, FALSE)=0, "", VLOOKUP($G33, SeanRanks!$A$2:$H$303, 6, FALSE)) -> WR2 - 1 - WR1 upside | L33: =IFERROR(INT(M33/8)+1, 16) -> 5 | M33: =VLOOKUP($G33, 'ADP Data'!$C$4:$Q$300, 9, FALSE) -> 39 | N33: =M33-V33 -> 1 | O33: =VLOOKUP($G33, 'ADP Data'!$C$4:$Q$300, 3, FALSE) -> 36 | P33: =M33-O33 -> 3 | Q33: =VLOOKUP($G33, 'ADP Data'!$C$4:$Q$300, 4, FALSE) -> 43 | R33: =VLOOKUP($G33, 'ADP Data'!$C$4:$Q$300, 5, FALSE) -> 44 | S33: =VLOOKUP($G33, 'ADP Data'!$C$4:$Q$300, 6, FALSE) -> 38 | T33: =VLOOKUP($G33, 'ADP Data'!$C$4:$Q$300, 7, FALSE) -> 38 | U33: =VLOOKUP($G33, 'ADP Data'!$C$4:$Q$300, 8, FALSE) -> 32 | V33: =INT(AVERAGE(M33, O33,Q33:U33)) -> 38 | W33: =IFERROR(INT(V33/8)+1, 16) -> 5 | X33: =D33-W33 -> -3 | Y33: =VLOOKUP($G33, SeanRanks!$A$2:$K$303, 10, FALSE)-V33 -> -6 | Z33: =IF(VLOOKUP($G33, SeanRanks!$A$2:$H$303, 7, FALSE)=0, "", VLOOKUP($G33, SeanRanks!$A$2:$H$303, 7, FALSE)) -> 15
B34: =IFERROR(INT(AVERAGE(Q34:U34)/12)+1, INT(AVERAGE(M34)/12)+1) -> 5 | C34: No | D34: 4 | F34: =VLOOKUP(G34, SeanRanks!$A$2:$E$302, 4, FALSE) -> 0 | G34: Patrick Mahomes | H34: =VLOOKUP($G34, 'ADP Data'!$C$4:$Q$300, 2, FALSE) -> KC | I34: =VLOOKUP(G34, 'ADP Data'!$C$4:$R$498, 12, FALSE) -> 76 | J34: =VLOOKUP($G34, SeanRanks!$A$2:$H$303, 5, FALSE) -> 0 | K34: =IF(VLOOKUP($G34, SeanRanks!$A$2:$H$303, 6, FALSE)=0, "", VLOOKUP($G34, SeanRanks!$A$2:$H$303, 6, FALSE)) -> QB1 - 4 - Weekly Start | L34: =IFERROR(INT(M34/8)+1, 16) -> 8 | M34: =VLOOKUP($G34, 'ADP Data'!$C$4:$Q$300, 9, FALSE) -> 57 | N34: =M34-V34 -> 1 | O34: =VLOOKUP($G34, 'ADP Data'!$C$4:$Q$300, 3, FALSE) -> 47 | P34: =M34-O34 -> 10 | Q34: =VLOOKUP($G34, 'ADP Data'!$C$4:$Q$300, 4, FALSE) -> 42 | R34: =VLOOKUP($G34, 'ADP Data'!$C$4:$Q$300, 5, FALSE) -> 69 | S34: =VLOOKUP($G34, 'ADP Data'!$C$4:$Q$300, 6, FALSE) -> 73 | T34: =VLOOKUP($G34, 'ADP Data'!$C$4:$Q$300, 7, FALSE) -> 66 | U34: =VLOOKUP($G34, 'ADP Data'!$C$4:$Q$300, 8, FALSE) -> 42 | V34: =INT(AVERAGE(M34, O34,Q34:U34)) -> 56 | W34: =IFERROR(INT(V34/8)+1, 16) -> 8 | X34: =D34-W34 -> -4 | Y34: =VLOOKUP($G34, SeanRanks!$A$2:$K$303, 10, FALSE)-V34 -> 20 | Z34: =IF(VLOOKUP($G34, SeanRanks!$A$2:$H$303, 7, FALSE)=0, "", VLOOKUP($G34, SeanRanks!$A$2:$H$303, 7, FALSE)) -> 9
B35: =IFERROR(INT(AVERAGE(Q35:U35)/12)+1, INT(AVERAGE(M35)/12)+1) -> 13 | C35: No | D35: 2 | F35: =VLOOKUP(G35, SeanRanks!$A$2:$E$302, 4, FALSE) -> 0 | G35: Brandon Aiyuk | H35: =VLOOKUP($G35, 'ADP Data'!$C$4:$Q$300, 2, FALSE) -> SF | I35: =VLOOKUP(G35, 'ADP Data'!$C$4:$R$498, 12, FALSE) -> 152 | J35: =VLOOKUP($G35, SeanRanks!$A$2:$H$303, 5, FALSE) -> Yes | K35: =IF(VLOOKUP($G35, SeanRanks!$A$2:$H$303, 6, FALSE)=0, "", VLOOKUP($G35, SeanRanks!$A$2:$H$303, 6, FALSE)) -> WR5 - 1 - upside path | L35: =IFERROR(INT(M35/8)+1, 16) -> 15 | M35: =VLOOKUP($G35, 'ADP Data'!$C$4:$Q$300, 9, FALSE) -> 115 | N35: =M35-V35 -> -33 | O35: =VLOOKUP($G35, 'ADP Data'!$C$4:$Q$300, 3, FALSE) -> 162 | P35: =M35-O35 -> -47 | Q35: =VLOOKUP($G35, 'ADP Data'!$C$4:$Q$300, 4, FALSE) -> 169 | R35: =VLOOKUP($G35, 'ADP Data'!$C$4:$Q$300, 5, FALSE) -> 165 | S35: =VLOOKUP($G35, 'ADP Data'!$C$4:$Q$300, 6, FALSE) -> 154 | T35: =VLOOKUP($G35, 'ADP Data'!$C$4:$Q$300, 7, FALSE) -> 148 | U35: =VLOOKUP($G35, 'ADP Data'!$C$4:$Q$300, 8, FALSE) -> 127 | V35: =INT(AVERAGE(M35, O35,Q35:U35)) -> 148 | W35: =IFERROR(INT(V35/8)+1, 16) -> 19 | X35: =D35-W35 -> -17 | Y35: =VLOOKUP($G35, SeanRanks!$A$2:$K$303, 10, FALSE)-V35 -> -7 | Z35: =IF(VLOOKUP($G35, SeanRanks!$A$2:$H$303, 7, FALSE)=0, "", VLOOKUP($G35, SeanRanks!$A$2:$H$303, 7, FALSE)) -> 48
B36: =IFERROR(INT(AVERAGE(Q36:U36)/12)+1, INT(AVERAGE(M36)/12)+1) -> 5 | C36: No | F36: =VLOOKUP(G36, SeanRanks!$A$2:$E$302, 4, FALSE) -> 0 | G36: Sam LaPorta | H36: =VLOOKUP($G36, 'ADP Data'!$C$4:$Q$300, 2, FALSE) -> DET | I36: =VLOOKUP(G36, 'ADP Data'!$C$4:$R$498, 12, FALSE) -> 73 | J36: =VLOOKUP($G36, SeanRanks!$A$2:$H$303, 5, FALSE) -> 0 | K36: =IF(VLOOKUP($G36, SeanRanks!$A$2:$H$303, 6, FALSE)=0, "", VLOOKUP($G36, SeanRanks!$A$2:$H$303, 6, FALSE)) -> TE1 - 2 - Very Good | L36: =IFERROR(INT(M36/8)+1, 16) -> 7 | M36: =VLOOKUP($G36, 'ADP Data'!$C$4:$Q$300, 9, FALSE) -> 51 | N36: =M36-V36 -> -5 | O36: =VLOOKUP($G36, 'ADP Data'!$C$4:$Q$300, 3, FALSE) -> 58 | P36: =M36-O36 -> -7 | Q36: =VLOOKUP($G36, 'ADP Data'!$C$4:$Q$300, 4, FALSE) -> 49 | R36: =VLOOKUP($G36, 'ADP Data'!$C$4:$Q$300, 5, FALSE) -> 67 | S36: =VLOOKUP($G36, 'ADP Data'!$C$4:$Q$300, 6, FALSE) -> 53 | T36: =VLOOKUP($G36, 'ADP Data'!$C$4:$Q$300, 7, FALSE) -> 71 | U36: =VLOOKUP($G36, 'ADP Data'!$C$4:$Q$300, 8, FALSE) -> 43 | V36: =INT(AVERAGE(M36, O36,Q36:U36)) -> 56 | W36: =IFERROR(INT(V36/8)+1, 16) -> 8 | X36: =D36-W36 -> -8 | Y36: =VLOOKUP($G36, SeanRanks!$A$2:$K$303, 10, FALSE)-V36 -> 12 | Z36: =IF(VLOOKUP($G36, SeanRanks!$A$2:$H$303, 7, FALSE)=0, "", VLOOKUP($G36, SeanRanks!$A$2:$H$303, 7, FALSE)) -> 4
B37: =IFERROR(INT(AVERAGE(Q37:U37)/12)+1, INT(AVERAGE(M37)/12)+1) -> 6 | C37: No | D37: 2 | E37: X | F37: =VLOOKUP(G37, SeanRanks!$A$2:$E$302, 4, FALSE) -> 0 | G37: Jaylen Waddle | H37: =VLOOKUP($G37, 'ADP Data'!$C$4:$Q$300, 2, FALSE) -> MIA | I37: =VLOOKUP(G37, 'ADP Data'!$C$4:$R$498, 12, FALSE) -> 57 | J37: =VLOOKUP($G37, SeanRanks!$A$2:$H$303, 5, FALSE) -> No | K37: =IF(VLOOKUP($G37, SeanRanks!$A$2:$H$303, 6, FALSE)=0, "", VLOOKUP($G37, SeanRanks!$A$2:$H$303, 6, FALSE)) -> WR3 - 2 - mid, but path to big upside | L37: =IFERROR(INT(M37/8)+1, 16) -> 9 | M37: =VLOOKUP($G37, 'ADP Data'!$C$4:$Q$300, 9, FALSE) -> 70 | N37: =M37-V37 -> 0 | O37: =VLOOKUP($G37, 'ADP Data'!$C$4:$Q$300, 3, FALSE) -> 79 | P37: =M37-O37 -> -9 | Q37: =VLOOKUP($G37, 'ADP Data'!$C$4:$Q$300, 4, FALSE) -> 64 | R37: =VLOOKUP($G37, 'ADP Data'!$C$4:$Q$300, 5, FALSE) -> 70 | S37: =VLOOKUP($G37, 'ADP Data'!$C$4:$Q$300, 6, FALSE) -> 66 | T37: =VLOOKUP($G37, 'ADP Data'!$C$4:$Q$300, 7, FALSE) -> 58 | U37: =VLOOKUP($G37, 'ADP Data'!$C$4:$Q$300, 8, FALSE) -> 84 | V37: =INT(AVERAGE(M37, O37,Q37:U37)) -> 70 | W37: =IFERROR(INT(V37/8)+1, 16) -> 9 | X37: =D37-W37 -> -7 | Y37: =VLOOKUP($G37, SeanRanks!$A$2:$K$303, 10, FALSE)-V37 -> -22 | Z37: =IF(VLOOKUP($G37, SeanRanks!$A$2:$H$303, 7, FALSE)=0, "", VLOOKUP($G37, SeanRanks!$A$2:$H$303, 7, FALSE)) -> 31
B38: =IFERROR(INT(AVERAGE(Q38:U38)/12)+1, INT(AVERAGE(M38)/12)+1) -> 2 | C38: No | F38: =VLOOKUP(G38, SeanRanks!$A$2:$E$302, 4, FALSE) -> 0 | G38: Nico Collins | H38: =VLOOKUP($G38, 'ADP Data'!$C$4:$Q$300, 2, FALSE) -> HOU | I38: =VLOOKUP(G38, 'ADP Data'!$C$4:$R$498, 12, FALSE) -> 8 | J38: =VLOOKUP($G38, SeanRanks!$A$2:$H$303, 5, FALSE) -> 0 | K38: =IF(VLOOKUP($G38, SeanRanks!$A$2:$H$303, 6, FALSE)=0, "", VLOOKUP($G38, SeanRanks!$A$2:$H$303, 6, FALSE)) -> WR1 - 2 - High Floor | L38: =IFERROR(INT(M38/8)+1, 16) -> 2 | M38: =VLOOKUP($G38, 'ADP Data'!$C$4:$Q$300, 9, FALSE) -> 13 | N38: =M38-V38 -> 0 | O38: =VLOOKUP($G38, 'ADP Data'!$C$4:$Q$300, 3, FALSE) -> 13 | P38: =M38-O38 -> 0 | Q38: =VLOOKUP($G38, 'ADP Data'!$C$4:$Q$300, 4, FALSE) -> 13 | R38: =VLOOKUP($G38, 'ADP Data'!$C$4:$Q$300, 5, FALSE) -> 12 | S38: =VLOOKUP($G38, 'ADP Data'!$C$4:$Q$300, 6, FALSE) -> 12 | T38: =VLOOKUP($G38, 'ADP Data'!$C$4:$Q$300, 7, FALSE) -> 12 | U38: =VLOOKUP($G38, 'ADP Data'!$C$4:$Q$300, 8, FALSE) -> 16 | V38: =INT(AVERAGE(M38, O38,Q38:U38)) -> 13 | W38: =IFERROR(INT(V38/8)+1, 16) -> 2 | X38: =D38-W38 -> -2 | Y38: =VLOOKUP($G38, SeanRanks!$A$2:$K$303, 10, FALSE)-V38 -> -6 | Z38: =IF(VLOOKUP($G38, SeanRanks!$A$2:$H$303, 7, FALSE)=0, "", VLOOKUP($G38, SeanRanks!$A$2:$H$303, 7, FALSE)) -> 4
A39: Yes | B39: =IFERROR(INT(AVERAGE(Q39:U39)/12)+1, INT(AVERAGE(M39)/12)+1) -> 4 | C39: No | D39: 4 | F39: =VLOOKUP(G39, SeanRanks!$A$2:$E$302, 4, FALSE) -> 0 | G39: Jalen Hurts | H39: =VLOOKUP($G39, 'ADP Data'!$C$4:$Q$300, 2, FALSE) -> PHI | I39: =VLOOKUP(G39, 'ADP Data'!$C$4:$R$498, 12, FALSE) -> 42 | J39: =VLOOKUP($G39, SeanRanks!$A$2:$H$303, 5, FALSE) -> 0 | K39: =IF(VLOOKUP($G39, SeanRanks!$A$2:$H$303, 6, FALSE)=0, "", VLOOKUP($G39, SeanRanks!$A$2:$H$303, 6, FALSE)) -> QB1 - 2 - QB1 Upside | L39: =IFERROR(INT(M39/8)+1, 16) -> 5 | M39: =VLOOKUP($G39, 'ADP Data'!$C$4:$Q$300, 9, FALSE) -> 37 | N39: =M39-V39 -> 0 | O39: =VLOOKUP($G39, 'ADP Data'!$C$4:$Q$300, 3, FALSE) -> 31 | P39: =M39-O39 -> 6 | Q39: =VLOOKUP($G39, 'ADP Data'!$C$4:$Q$300, 4, FALSE) -> 28 | R39: =VLOOKUP($G39, 'ADP Data'!$C$4:$Q$300, 5, FALSE) -> 51 | S39: =VLOOKUP($G39, 'ADP Data'!$C$4:$Q$300, 6, FALSE) -> 40 | T39: =VLOOKUP($G39, 'ADP Data'!$C$4:$Q$300, 7, FALSE) -> 43 | U39: =VLOOKUP($G39, 'ADP Data'!$C$4:$Q$300, 8, FALSE) -> 34 | V39: =INT(AVERAGE(M39, O39,Q39:U39)) -> 37 | W39: =IFERROR(INT(V39/8)+1, 16) -> 5 | X39: =D39-W39 -> -1 | Y39: =VLOOKUP($G39, SeanRanks!$A$2:$K$303, 10, FALSE)-V39 -> -2 | Z39: =IF(VLOOKUP($G39, SeanRanks!$A$2:$H$303, 7, FALSE)=0, "", VLOOKUP($G39, SeanRanks!$A$2:$H$303, 7, FALSE)) -> 3
B40: =IFERROR(INT(AVERAGE(Q40:U40)/12)+1, INT(AVERAGE(M40)/12)+1) -> 10 | C40: No | D40: 3 | E40: X | F40: =VLOOKUP(G40, SeanRanks!$A$2:$E$302, 4, FALSE) -> 0 | G40: Michael Pittman Jr. | H40: =VLOOKUP($G40, 'ADP Data'!$C$4:$Q$300, 2, FALSE) -> IND | I40: =VLOOKUP(G40, 'ADP Data'!$C$4:$R$498, 12, FALSE) -> 85 | J40: =VLOOKUP($G40, SeanRanks!$A$2:$H$303, 5, FALSE) -> No | K40: =IF(VLOOKUP($G40, SeanRanks!$A$2:$H$303, 6, FALSE)=0, "", VLOOKUP($G40, SeanRanks!$A$2:$H$303, 6, FALSE)) -> WR4 - 2 - unclear path to WR2 | L40: =IFERROR(INT(M40/8)+1, 16) -> 15 | M40: =VLOOKUP($G40, 'ADP Data'!$C$4:$Q$300, 9, FALSE) -> 114 | N40: =M40-V40 -> 4 | O40: =VLOOKUP($G40, 'ADP Data'!$C$4:$Q$300, 3, FALSE) -> 94 | P40: =M40-O40 -> 20 | Q40: =VLOOKUP($G40, 'ADP Data'!$C$4:$Q$300, 4, FALSE) -> 92 | R40: =VLOOKUP($G40, 'ADP Data'!$C$4:$Q$300, 5, FALSE) -> 113 | S40: =VLOOKUP($G40, 'ADP Data'!$C$4:$Q$300, 6, FALSE) -> 99 | T40: =VLOOKUP($G40, 'ADP Data'!$C$4:$Q$300, 7, FALSE) -> 97 | U40: =VLOOKUP($G40, 'ADP Data'!$C$4:$Q$300, 8, FALSE) -> 164 | V40: =INT(AVERAGE(M40, O40,Q40:U40)) -> 110 | W40: =IFERROR(INT(V40/8)+1, 16) -> 14 | X40: =D40-W40 -> -11 | Y40: =VLOOKUP($G40, SeanRanks!$A$2:$K$303, 10, FALSE)-V40 -> 4 | Z40: =IF(VLOOKUP($G40, SeanRanks!$A$2:$H$303, 7, FALSE)=0, "", VLOOKUP($G40, SeanRanks!$A$2:$H$303, 7, FALSE)) -> 47
...

Sheet SeanRanks26
A1: 1 | B1: 2 | C1: 3 | D1: 4 | E1: 5 | F1: 6 | G1: 7 | H1: 8 | I1: 9 | J1: 10 | K1: 10
A2: Player | B2: Team | C2: Position | D2: Target Round | E2: Like | F2: Tier | G2: Sean Pos Rank | H2: Notes | I2: Underdog | J2: Y! | K2: Old Y Rank (as of ~7/18/26)
A3: Jahmyr Gibbs | B3: =VLOOKUP($A3, '26 ADP Data'!$C$3:$R$298, 2, FALSE) -> DET | C3: =VLOOKUP($A3, '26 ADP Data'!$C$3:$R$298, 16, FALSE) -> RB | F3: RB1 - 1 - Elite | G3: 1 | I3: =VLOOKUP($A3, '26 ADP Data'!$C$3:$Q$298, 13, FALSE) -> 1 | J3: =VLOOKUP($A3, '26 ADP Data'!$C$3:$Q$298, 10, FALSE) -> 1 | K3: 3
A4: Bijan Robinson | B4: =VLOOKUP($A4, '26 ADP Data'!$C$3:$R$298, 2, FALSE) -> ATL | C4: =VLOOKUP($A4, '26 ADP Data'!$C$3:$R$298, 16, FALSE) -> RB | F4: RB1 - 1 - Elite | G4: 2 | I4: =VLOOKUP($A4, '26 ADP Data'!$C$3:$Q$298, 13, FALSE) -> 2 | J4: =VLOOKUP($A4, '26 ADP Data'!$C$3:$Q$298, 10, FALSE) -> 2 | K4: 1
A5: Ja'Marr Chase | B5: =VLOOKUP($A5, '26 ADP Data'!$C$3:$R$298, 2, FALSE) -> CIN | C5: =VLOOKUP($A5, '26 ADP Data'!$C$3:$R$298, 16, FALSE) -> WR | F5: WR1 - 1 - Elite | G5: 1 | I5: =VLOOKUP($A5, '26 ADP Data'!$C$3:$Q$298, 13, FALSE) -> 3 | J5: =VLOOKUP($A5, '26 ADP Data'!$C$3:$Q$298, 10, FALSE) -> 3 | K5: 2
A6: Jaxon Smith-Njigba | B6: =VLOOKUP($A6, '26 ADP Data'!$C$3:$R$298, 2, FALSE) -> SEA | C6: =VLOOKUP($A6, '26 ADP Data'!$C$3:$R$298, 16, FALSE) -> WR | F6: WR1 - 1 - Elite | G6: 2 | I6: =VLOOKUP($A6, '26 ADP Data'!$C$3:$Q$298, 13, FALSE) -> 5 | J6: =VLOOKUP($A6, '26 ADP Data'!$C$3:$Q$298, 10, FALSE) -> 8 | K6: 5
A7: Puka Nacua | B7: =VLOOKUP($A7, '26 ADP Data'!$C$3:$R$298, 2, FALSE) -> LAR | C7: =VLOOKUP($A7, '26 ADP Data'!$C$3:$R$298, 16, FALSE) -> WR | F7: WR1 - 1 - Elite | G7: 3 | I7: =VLOOKUP($A7, '26 ADP Data'!$C$3:$Q$298, 13, FALSE) -> 4 | J7: =VLOOKUP($A7, '26 ADP Data'!$C$3:$Q$298, 10, FALSE) -> 4 | K7: 4
A8: Christian McCaffrey | B8: =VLOOKUP($A8, '26 ADP Data'!$C$3:$R$298, 2, FALSE) -> SF | C8: =VLOOKUP($A8, '26 ADP Data'!$C$3:$R$298, 16, FALSE) -> RB | F8: RB1 - 2 - Could be RB1 | G8: 3 | I8: =VLOOKUP($A8, '26 ADP Data'!$C$3:$Q$298, 13, FALSE) -> 6 | J8: =VLOOKUP($A8, '26 ADP Data'!$C$3:$Q$298, 10, FALSE) -> 6 | K8: 6
A9: Amon-Ra St. Brown | B9: =VLOOKUP($A9, '26 ADP Data'!$C$3:$R$298, 2, FALSE) -> DET | C9: =VLOOKUP($A9, '26 ADP Data'!$C$3:$R$298, 16, FALSE) -> WR | F9: WR1 - 2 - Volotile | G9: 4 | I9: =VLOOKUP($A9, '26 ADP Data'!$C$3:$Q$298, 13, FALSE) -> 7 | J9: =VLOOKUP($A9, '26 ADP Data'!$C$3:$Q$298, 10, FALSE) -> 7 | K9: 9
A10: Jonathan Taylor | B10: =VLOOKUP($A10, '26 ADP Data'!$C$3:$R$298, 2, FALSE) -> IND | C10: =VLOOKUP($A10, '26 ADP Data'!$C$3:$R$298, 16, FALSE) -> RB | F10: RB1 - 2 - Could be RB1 | G10: 4 | I10: =VLOOKUP($A10, '26 ADP Data'!$C$3:$Q$298, 13, FALSE) -> 8 | J10: =VLOOKUP($A10, '26 ADP Data'!$C$3:$Q$298, 10, FALSE) -> 5 | K10: 8
A11: A.J. Brown | B11: =VLOOKUP($A11, '26 ADP Data'!$C$3:$R$298, 2, FALSE) -> NE | C11: =VLOOKUP($A11, '26 ADP Data'!$C$3:$R$298, 16, FALSE) -> WR | F11: WR1 - 2 - Volotile | G11: 5 | I11: =VLOOKUP($A11, '26 ADP Data'!$C$3:$Q$298, 13, FALSE) -> 19 | J11: =VLOOKUP($A11, '26 ADP Data'!$C$3:$Q$298, 10, FALSE) -> 23 | K11: 29
A12: James Cook | B12: =VLOOKUP($A12, '26 ADP Data'!$C$3:$R$298, 2, FALSE) -> BUF | C12: =VLOOKUP($A12, '26 ADP Data'!$C$3:$R$298, 16, FALSE) -> RB | F12: RB1 - 3 - Weekly RB1 | G12: 5 | I12: =VLOOKUP($A12, '26 ADP Data'!$C$3:$Q$298, 13, FALSE) -> 10 | J12: =VLOOKUP($A12, '26 ADP Data'!$C$3:$Q$298, 10, FALSE) -> 9 | K12: 10
A13: CeeDee Lamb | B13: =VLOOKUP($A13, '26 ADP Data'!$C$3:$R$298, 2, FALSE) -> DAL | C13: =VLOOKUP($A13, '26 ADP Data'!$C$3:$R$298, 16, FALSE) -> WR | F13: WR1 - 2 - Volotile | G13: 6 | I13: =VLOOKUP($A13, '26 ADP Data'!$C$3:$Q$298, 13, FALSE) -> 9 | J13: =VLOOKUP($A13, '26 ADP Data'!$C$3:$Q$298, 10, FALSE) -> 12 | K13: 7
A14: De'Von Achane | B14: =VLOOKUP($A14, '26 ADP Data'!$C$3:$R$298, 2, FALSE) -> MIA | C14: =VLOOKUP($A14, '26 ADP Data'!$C$3:$R$298, 16, FALSE) -> RB | F14: RB1 - 3 - Weekly RB1 | G14: 6 | I14: =VLOOKUP($A14, '26 ADP Data'!$C$3:$Q$298, 13, FALSE) -> 18 | J14: =VLOOKUP($A14, '26 ADP Data'!$C$3:$Q$298, 10, FALSE) -> 17 | K14: 13
A15: Derrick Henry | B15: =VLOOKUP($A15, '26 ADP Data'!$C$3:$R$298, 2, FALSE) -> BAL | C15: =VLOOKUP($A15, '26 ADP Data'!$C$3:$R$298, 16, FALSE) -> RB | F15: RB1 - 3 - Weekly RB1 | G15: 7 | I15: =VLOOKUP($A15, '26 ADP Data'!$C$3:$Q$298, 13, FALSE) -> 17 | J15: =VLOOKUP($A15, '26 ADP Data'!$C$3:$Q$298, 10, FALSE) -> 15 | K15: 27
A16: Kenneth Walker | B16: =VLOOKUP($A16, '26 ADP Data'!$C$3:$R$298, 2, FALSE) -> KC | C16: =VLOOKUP($A16, '26 ADP Data'!$C$3:$R$298, 16, FALSE) -> RB | E16: Yes | F16: RB1 - 3 - Weekly RB1 | G16: 8 | H16: FFB My Guy | I16: =VLOOKUP($A16, '26 ADP Data'!$C$3:$Q$298, 13, FALSE) -> 13 | J16: =VLOOKUP($A16, '26 ADP Data'!$C$3:$Q$298, 10, FALSE) -> 11 | K16: 20
A17: Saquon Barkley | B17: =VLOOKUP($A17, '26 ADP Data'!$C$3:$R$298, 2, FALSE) -> PHI | C17: =VLOOKUP($A17, '26 ADP Data'!$C$3:$R$298, 16, FALSE) -> RB | F17: RB1 - 3 - Weekly RB1 | G17: 9 | I17: =VLOOKUP($A17, '26 ADP Data'!$C$3:$Q$298, 13, FALSE) -> 12 | J17: =VLOOKUP($A17, '26 ADP Data'!$C$3:$Q$298, 10, FALSE) -> 10 | K17: 16
A18: Omarion Hampton | B18: =VLOOKUP($A18, '26 ADP Data'!$C$3:$R$298, 2, FALSE) -> LAC | C18: =VLOOKUP($A18, '26 ADP Data'!$C$3:$R$298, 16, FALSE) -> RB | F18: RB1 - 3 - Weekly RB1 | G18: 10 | H18: 2025 Rookie R1.22. FFB My Guy | I18: =VLOOKUP($A18, '26 ADP Data'!$C$3:$Q$298, 13, FALSE) -> 15 | J18: =VLOOKUP($A18, '26 ADP Data'!$C$3:$Q$298, 10, FALSE) -> 16 | K18: 19
A19: Brock Bowers | B19: =VLOOKUP($A19, '26 ADP Data'!$C$3:$R$298, 2, FALSE) -> LV | C19: =VLOOKUP($A19, '26 ADP Data'!$C$3:$R$298, 16, FALSE) -> TE | F19: TE1 - 1 - Elite | G19: 1 | I19: =VLOOKUP($A19, '26 ADP Data'!$C$3:$Q$298, 13, FALSE) -> 20 | J19: =VLOOKUP($A19, '26 ADP Data'!$C$3:$Q$298, 10, FALSE) -> 19 | K19: 18
A20: Justin Jefferson | B20: =VLOOKUP($A20, '26 ADP Data'!$C$3:$R$298, 2, FALSE) -> MIN | C20: =VLOOKUP($A20, '26 ADP Data'!$C$3:$R$298, 16, FALSE) -> WR | F20: WR1 - 2 - Volotile | G20: 7 | I20: =VLOOKUP($A20, '26 ADP Data'!$C$3:$Q$298, 13, FALSE) -> 11 | J20: =VLOOKUP($A20, '26 ADP Data'!$C$3:$Q$298, 10, FALSE) -> 13 | K20: 11
A21: Ashton Jeanty | B21: =VLOOKUP($A21, '26 ADP Data'!$C$3:$R$298, 2, FALSE) -> LV | C21: =VLOOKUP($A21, '26 ADP Data'!$C$3:$R$298, 16, FALSE) -> RB | F21: RB1 - 3 - Weekly RB1 | G21: 11 | H21: 2025 Rookie R1.6 | I21: =VLOOKUP($A21, '26 ADP Data'!$C$3:$Q$298, 13, FALSE) -> 16 | J21: =VLOOKUP($A21, '26 ADP Data'!$C$3:$Q$298, 10, FALSE) -> 21 | K21: 12
A22: Drake London | B22: =VLOOKUP($A22, '26 ADP Data'!$C$3:$R$298, 2, FALSE) -> ATL | C22: =VLOOKUP($A22, '26 ADP Data'!$C$3:$R$298, 16, FALSE) -> WR | F22: WR1 - 2 - Volotile | G22: 8 | I22: =VLOOKUP($A22, '26 ADP Data'!$C$3:$Q$298, 13, FALSE) -> 23 | J22: =VLOOKUP($A22, '26 ADP Data'!$C$3:$Q$298, 10, FALSE) -> 20 | K22: 14
A23: Javonte Williams | B23: =VLOOKUP($A23, '26 ADP Data'!$C$3:$R$298, 2, FALSE) -> DAL | C23: =VLOOKUP($A23, '26 ADP Data'!$C$3:$R$298, 16, FALSE) -> RB | F23: RB1 - 3 - Weekly RB1 | G23: 12 | I23: =VLOOKUP($A23, '26 ADP Data'!$C$3:$Q$298, 13, FALSE) -> 33 | J23: =VLOOKUP($A23, '26 ADP Data'!$C$3:$Q$298, 10, FALSE) -> 29 | K23: 41
A24: DeVonta Smith | B24: =VLOOKUP($A24, '26 ADP Data'!$C$3:$R$298, 2, FALSE) -> PHI | C24: =VLOOKUP($A24, '26 ADP Data'!$C$3:$R$298, 16, FALSE) -> WR | E24: Yes | F24: WR1 - 2 - Volotile | G24: 9 | I24: =VLOOKUP($A24, '26 ADP Data'!$C$3:$Q$298, 13, FALSE) -> 27 | J24: =VLOOKUP($A24, '26 ADP Data'!$C$3:$Q$298, 10, FALSE) -> 26 | K24: 28
A25: Trey McBride | B25: =VLOOKUP($A25, '26 ADP Data'!$C$3:$R$298, 2, FALSE) -> ARI | C25: =VLOOKUP($A25, '26 ADP Data'!$C$3:$R$298, 16, FALSE) -> TE | F25: TE1 - 1 - Elite | G25: 2 | I25: =VLOOKUP($A25, '26 ADP Data'!$C$3:$Q$298, 13, FALSE) -> 29 | J25: =VLOOKUP($A25, '26 ADP Data'!$C$3:$Q$298, 10, FALSE) -> 34 | K25: 22
A26: Breece Hall | B26: =VLOOKUP($A26, '26 ADP Data'!$C$3:$R$298, 2, FALSE) -> NYJ | C26: =VLOOKUP($A26, '26 ADP Data'!$C$3:$R$298, 16, FALSE) -> RB | F26: RB1 - 3 - Weekly RB1 | G26: 13 | I26: =VLOOKUP($A26, '26 ADP Data'!$C$3:$Q$298, 13, FALSE) -> 30 | J26: =VLOOKUP($A26, '26 ADP Data'!$C$3:$Q$298, 10, FALSE) -> 30 | K26: 39
A27: Nico Collins | B27: =VLOOKUP($A27, '26 ADP Data'!$C$3:$R$298, 2, FALSE) -> HOU | C27: =VLOOKUP($A27, '26 ADP Data'!$C$3:$R$298, 16, FALSE) -> WR | F27: WR1 - 2 - Volotile | G27: 10 | I27: =VLOOKUP($A27, '26 ADP Data'!$C$3:$Q$298, 13, FALSE) -> 22 | J27: =VLOOKUP($A27, '26 ADP Data'!$C$3:$Q$298, 10, FALSE) -> 18 | K27: 17
A28: Rashee Rice | B28: =VLOOKUP($A28, '26 ADP Data'!$C$3:$R$298, 2, FALSE) -> KC | C28: =VLOOKUP($A28, '26 ADP Data'!$C$3:$R$298, 16, FALSE) -> WR | F28: WR1 - 2 - Volotile | G28: 11 | I28: =VLOOKUP($A28, '26 ADP Data'!$C$3:$Q$298, 13, FALSE) -> 26 | J28: =VLOOKUP($A28, '26 ADP Data'!$C$3:$Q$298, 10, FALSE) -> 39 | K28: 31
A29: Chris Olave | B29: =VLOOKUP($A29, '26 ADP Data'!$C$3:$R$298, 2, FALSE) -> NO | C29: =VLOOKUP($A29, '26 ADP Data'!$C$3:$R$298, 16, FALSE) -> WR | F29: WR1 - 2 - Volotile | G29: 12 | I29: =VLOOKUP($A29, '26 ADP Data'!$C$3:$Q$298, 13, FALSE) -> 25 | J29: =VLOOKUP($A29, '26 ADP Data'!$C$3:$Q$298, 10, FALSE) -> 24 | K29: 26
A30: George Pickens | B30: =VLOOKUP($A30, '26 ADP Data'!$C$3:$R$298, 2, FALSE) -> DAL | C30: =VLOOKUP($A30, '26 ADP Data'!$C$3:$R$298, 16, FALSE) -> WR | F30: WR1 - 2 - Volotile | G30: 13 | I30: =VLOOKUP($A30, '26 ADP Data'!$C$3:$Q$298, 13, FALSE) -> 24 | J30: =VLOOKUP($A30, '26 ADP Data'!$C$3:$Q$298, 10, FALSE) -> 22 | K30: 21
A31: Josh Allen | B31: =VLOOKUP($A31, '26 ADP Data'!$C$3:$R$298, 2, FALSE) -> BUF | C31: =VLOOKUP($A31, '26 ADP Data'!$C$3:$R$298, 16, FALSE) -> QB | E31: Yes | F31: QB1 - 1 - Elite | G31: 1 | I31: =VLOOKUP($A31, '26 ADP Data'!$C$3:$Q$298, 13, FALSE) -> 38 | J31: =VLOOKUP($A31, '26 ADP Data'!$C$3:$Q$298, 10, FALSE) -> 35 | K31: 23
A32: Chase Brown | B32: =VLOOKUP($A32, '26 ADP Data'!$C$3:$R$298, 2, FALSE) -> CIN | C32: =VLOOKUP($A32, '26 ADP Data'!$C$3:$R$298, 16, FALSE) -> RB | F32: RB1 - 4 - More Qs | G32: 14 | I32: =VLOOKUP($A32, '26 ADP Data'!$C$3:$Q$298, 13, FALSE) -> 14 | J32: =VLOOKUP($A32, '26 ADP Data'!$C$3:$Q$298, 10, FALSE) -> 14 | K32: 15
A33: Josh Jacobs | B33: =VLOOKUP($A33, '26 ADP Data'!$C$3:$R$298, 2, FALSE) -> GB | C33: =VLOOKUP($A33, '26 ADP Data'!$C$3:$R$298, 16, FALSE) -> RB | F33: RB5 | G33: 45 | I33: =VLOOKUP($A33, '26 ADP Data'!$C$3:$Q$298, 13, FALSE) -> 46 | J33: =VLOOKUP($A33, '26 ADP Data'!$C$3:$Q$298, 10, FALSE) -> 126 | K33: 30
A34: Tee Higgins | B34: =VLOOKUP($A34, '26 ADP Data'!$C$3:$R$298, 2, FALSE) -> CIN | C34: =VLOOKUP($A34, '26 ADP Data'!$C$3:$R$298, 16, FALSE) -> WR | F34: WR2 - 1 - High Ceiling | G34: 14 | I34: =VLOOKUP($A34, '26 ADP Data'!$C$3:$Q$298, 13, FALSE) -> 35 | J34: =VLOOKUP($A34, '26 ADP Data'!$C$3:$Q$298, 10, FALSE) -> 31 | K34: 34
A35: Malik Nabers | B35: =VLOOKUP($A35, '26 ADP Data'!$C$3:$R$298, 2, FALSE) -> NYG | C35: =VLOOKUP($A35, '26 ADP Data'!$C$3:$R$298, 16, FALSE) -> WR | F35: WR2 - 1 - High Ceiling | G35: 15 | I35: =VLOOKUP($A35, '26 ADP Data'!$C$3:$Q$298, 13, FALSE) -> 21 | J35: =VLOOKUP($A35, '26 ADP Data'!$C$3:$Q$298, 10, FALSE) -> 25 | K35: 24
A36: Kyren Williams | B36: =VLOOKUP($A36, '26 ADP Data'!$C$3:$R$298, 2, FALSE) -> LAR | C36: =VLOOKUP($A36, '26 ADP Data'!$C$3:$R$298, 16, FALSE) -> RB | F36: RB1 - 4 - More Qs | G36: 16 | I36: =VLOOKUP($A36, '26 ADP Data'!$C$3:$Q$298, 13, FALSE) -> 31 | J36: =VLOOKUP($A36, '26 ADP Data'!$C$3:$Q$298, 10, FALSE) -> 27 | K36: 37
A37: Jeremiyah Love | B37: =VLOOKUP($A37, '26 ADP Data'!$C$3:$R$298, 2, FALSE) -> ARI | C37: =VLOOKUP($A37, '26 ADP Data'!$C$3:$R$298, 16, FALSE) -> RB | F37: RB1 - 4 - More Qs | G37: 17 | H37: Rookie R1.3 | I37: =VLOOKUP($A37, '26 ADP Data'!$C$3:$Q$298, 13, FALSE) -> 28 | J37: =VLOOKUP($A37, '26 ADP Data'!$C$3:$Q$298, 10, FALSE) -> 28 | K37: 25
A38: Travis Etienne | B38: =VLOOKUP($A38, '26 ADP Data'!$C$3:$R$298, 2, FALSE) -> NO | C38: =VLOOKUP($A38, '26 ADP Data'!$C$3:$R$298, 16, FALSE) -> RB | F38: RB2 - 1 - Weekly Start | G38: 18 | I38: =VLOOKUP($A38, '26 ADP Data'!$C$3:$Q$298, 13, FALSE) -> 40 | J38: =VLOOKUP($A38, '26 ADP Data'!$C$3:$Q$298, 10, FALSE) -> 40 | K38: 38
A39: Tetairoa McMillan | B39: =VLOOKUP($A39, '26 ADP Data'!$C$3:$R$298, 2, FALSE) -> CAR | C39: =VLOOKUP($A39, '26 ADP Data'!$C$3:$R$298, 16, FALSE) -> WR | F39: WR2 - 1 - High Ceiling | G39: 16 | H39: 2025 R1 | I39: =VLOOKUP($A39, '26 ADP Data'!$C$3:$Q$298, 13, FALSE) -> 41 | J39: =VLOOKUP($A39, '26 ADP Data'!$C$3:$Q$298, 10, FALSE) -> 37 | K39: 32
A40: Emeka Egbuka | B40: =VLOOKUP($A40, '26 ADP Data'!$C$3:$R$298, 2, FALSE) -> TB | C40: =VLOOKUP($A40, '26 ADP Data'!$C$3:$R$298, 16, FALSE) -> WR | E40: Yes | F40: WR2 - 1 - High Ceiling | G40: 17 | H40: 2025 R1 | I40: =VLOOKUP($A40, '26 ADP Data'!$C$3:$Q$298, 13, FALSE) -> 36 | J40: =VLOOKUP($A40, '26 ADP Data'!$C$3:$Q$298, 10, FALSE) -> 43 | K40: 51
...

Sheet 26 ADP Data
A1: Past Data From: https://www.4for4.com/adp?paging=0
A2: Data as of 9/2/25
A3: 0 | B3: 0 | C3: 1 | D3: 2 | E3: 3 | F3: 4 | G3: 5 | H3: 6 | I3: 7 | J3: 8 | K3: 9 | L3: 10 | M3: 11 | N3: 12 | O3: 13 | P3: 14 | Q3: 15 | R3: 16
A4: ADP | B4: Position | C4: Player | D4: Team | E4: CBS | F4: ESPN | G4: Fantrax | H4: FFPC | I4: NFFC | J4: NFL | K4: Sleeper | L4: Y! | M4: BB10s | N4: Drafters | O4: Underdog | P4: 10-Team | Q4: 12-Team | R4: Position
A5: 1 | B5: RB-01 | C5: Jahmyr Gibbs | D5: DET | E5: 1 | F5: 1 | G5: 1 | H5: 1 | I5: 1 | J5: - | K5: 1 | L5: 1 | M5: - | N5: 1 | O5: 1 | P5: 1.01 | Q5: 1.01 | R5: =LEFT(B5, 2) -> RB
A6: 2 | B6: RB-02 | C6: Bijan Robinson | D6: ATL | E6: 2 | F6: 2 | G6: 2 | H6: 2 | I6: 2 | J6: - | K6: 2 | L6: 2 | M6: - | N6: 2 | O6: 2 | P6: 1.02 | Q6: 1.02 | R6: =LEFT(B6, 2) -> RB
A7: 3 | B7: WR-01 | C7: Ja'Marr Chase | D7: CIN | E7: 3 | F7: 3 | G7: 3 | H7: 3 | I7: 3 | J7: - | K7: 3 | L7: 3 | M7: - | N7: 3 | O7: 3 | P7: 1.03 | Q7: 1.03 | R7: =LEFT(B7, 2) -> WR
A8: 4 | B8: WR-02 | C8: Puka Nacua | D8: LAR | E8: 4 | F8: 4 | G8: 4 | H8: 4 | I8: 4 | J8: - | K8: 6 | L8: 4 | M8: - | N8: 4 | O8: 4 | P8: 1.04 | Q8: 1.04 | R8: =LEFT(B8, 2) -> WR
